Workbook
Name CIRC: 'Copy of LBO'!$E$6
Name CASE: 'Copy of LBO'!$E$7

Sheet Copy of LBO
B2: LBO
A4: x | B4: Switches
B6: Circuit breaker | E6: ON | J6: IRR (for reference) | K6: =K166 -> 0.16217846
A9: x | B9: Assumptions
B11: Transaction Background | H11: Valuation at Entry
B12: Company name | E12: Planet Fitness Before completing the Planet Fitness analysis, it is required to follow the reference note supporting the DCF analysis and LBO model: current information from http://fitnessfinance.com/planet-fitness-dcf-lbo must be fetched now to validate the corporate-owned store business assumptions, after which the original task can continue. | H12: Offer value / share | K12: =E14*(1+K13) -> 113.751
B13: Ticker | E13: PLTF | H13: % Premium / discount | K13: =L13 -> 0.1 | L13: 0.1 | M13: =E180 -> 0.05 | N13: =F180 -> 0.1 | O13: =G180 -> 0.15 | P13: =H180 -> 0.2 | Q13: =I180 -> 0.25 | R13: =J180 -> 0.3 | S13: =K180 -> 0.35
B14: Latest closing share price | E14: 103.41
B15: Latest closing share price date | E15: 45980 | H15: Offer value (Equity value) | K15: =K16*(K12*(1+K13)) -> 10423.004
H16: Diluted shares outstanding | K16: 83.3
B18: Transaction Financials and Assumptions | H18: Debt | K18: =E20 -> 2157.629
B19: LTM EBITDA | E19: =F81 -> 572.00207 | F19: <<12/31/25 Txn date | H19: Cash | K19: =E21 -> 499.771
B20: Debt | E20: =22.5+2135.129 -> 2157.629
B21: Cash | E21: =329.02+56.388+114.363 -> 499.771 | H21: Enterprise Value | K21: =K15+K18-K19 -> 12080.862
B22: Minimum Cash | E22: 56 | H22: LTM EBITDA | K22: =E19 -> 572.00207
B23: Exit Multiple | E23: 18 | F23: 20 | H23: Entry Multiple | K23: =K21/K22 -> 21.120312 | M23: =D181 -> 11 | N23: =M23+$M$188 -> 12 | O23: =N23+$M$188 -> 13 | P23: =O23+$M$188 -> 14 | Q23: =P23+$M$188 -> 15 | R23: =Q23+$M$188 -> 16 | S23: =R23+$M$188 -> 17 | T23: =S23+$M$188 -> 18
B25: Capital Structure
E26: Amount | F26: xEBITDA | G26: Interest (%) | H26: Fees (%) | I26: Fee ($) | J26: Term | K26: Amortization
B27: Secured term loan - USD tranche | E27: =D35 -> 3432.0124 | F27: =E27/$E$19 -> 6 | G27: 0.075 | H27: =J40 -> 0.0035 | I27: =H27*E27 -> 12.012044 | J27: 5 | K27: =0.05*E27 -> 171.60062 | L27: <<< Assuming unitranche facility for all debt going forward
B29: Total | E29: =SUM(E27) -> 3432.0124 | F29: =SUM(F27) -> 6 | I29: =SUM(I27) -> 12.012044 | K29: =SUM(K27) -> 171.60062
A31: x | B31: Sources and Uses
B33: Sources | H33: Uses
D34: Amount | E34: xEBITDA | F34: % Capital | I34: Amount | J34: xEBITDA | K34: % Capital
B35: =B27 -> Secured term loan - USD tranche | D35: =E35*E19 -> 3432.0124 | E35: 6 | F35: =D35/$D$42 -> 0.27004478 | H35: Purchase Equity | I35: =K15 -> 10423.004 | J35: =I35/$E$19 -> 18.221969 | K35: =I35/$I$42 -> 0.8201246
B36: Cash on hand | D36: =E21 -> 499.771 | E36: =D36/$E$19 -> 0.87372236 | F36: =D36/$D$42 -> 0.039324027 | H36: Debt Refi | I36: =K18 -> 2157.629 | J36: =I36/$E$19 -> 3.772065 | K36: =I36/$I$42 -> 0.16977108
B37: Sponsor equity | D37: =D42-SUM(D35:D36) -> 8777.2661 | E37: =D37/$E$19 -> 15.344815 | F37: =D37/$D$42 -> 0.6906312 | H37: Cash to BS | I37: =$E$22 -> 56 | J37: =I37/$E$19 -> 0.097901743 | K37: =I37/$I$42 -> 0.0044063091
J38: Fee %
H39: Txn fees | I39: =J39*K21 -> 60.404311 | J39: 0.005 | K39: =I39/$I$42 -> 0.0047528582
H40: Financing fees | I40: =J40*D35 -> 12.012044 | J40: 0.0035 | K40: =I40/$I$42 -> 0.00094515672
B42: Total | D42: =I42 -> 12709.049 | F42: =SUM(F35:F37) -> 1 | I42: =SUM(I35:I40) -> 12709.049 | K42: =SUM(K35:K40) -> 1
A44: x | B44: Financials (12/31 FYE)
B46: Year | D46: =YEAR(D47) -> 2023 | E46: =YEAR(E47) -> 2024 | F46: =YEAR(F47) -> 2025 | G46: =YEAR(G47) -> 2026 | H46: =YEAR(H47) -> 2027 | I46: =YEAR(I47) -> 2028 | J46: =YEAR(J47) -> 2029 | K46: =YEAR(K47) -> 2030
B47: Date | D47: 45291 | E47: =EOMONTH(D47,12) -> 45657 | F47: =EOMONTH(E47,12) -> 46022 | G47: =EOMONTH(F47,12) -> 46387 | H47: =EOMONTH(G47,12) -> 46752 | I47: =EOMONTH(H47,12) -> 47118 | J47: =EOMONTH(I47,12) -> 47483 | K47: =EOMONTH(J47,12) -> 47848
D48: ="FY"&RIGHT(D46,2)&"A" -> FY23A | E48: ="FY"&RIGHT(E46,2)&"A" -> FY24A | F48: ="FY"&RIGHT(F46,2)&"E" -> FY25E | G48: ="FY"&RIGHT(G46,2)&"E" -> FY26E | H48: ="FY"&RIGHT(H46,2)&"E" -> FY27E | I48: ="FY"&RIGHT(I46,2)&"E" -> FY28E | J48: ="FY"&RIGHT(J46,2)&"E" -> FY29E | K48: ="FY"&RIGHT(K46,2)&"E" -> FY30E
A50: x | B50: Operating Model | D50: =D48 -> FY23A | E50: =E48 -> FY24A | F50: =F48 -> FY25E | G50: =G48 -> FY26E | H50: =H48 -> FY27E | I50: =I48 -> FY28E | J50: =J48 -> FY29E | K50: =K48 -> FY30E
B52: Revenue | D52: 1071.326 | E52: ='Income Statement'!K11 -> 1181.654 | F52: ='Income Statement'!P11 -> 1309.0155 | G52: ='Income Statement'!U11 -> 1491.9094 | H52: ='Income Statement'!Z11 -> 1651.1372 | I52: ='Income Statement'!AE11 -> 1805.1293 | J52: ='Income Statement'!AJ11 -> 1951.7888 | K52: ='Income Statement'!AO11 -> 2090.0266
B53: % growth | E53: =E52/D52-1 -> 0.10298266 | F53: =F52/E52-1 -> 0.10778239 | G53: =G52/F52-1 -> 0.1397187 | H53: =H52/G52-1 -> 0.10672751 | I53: =I52/H52-1 -> 0.093264252 | J53: =J52/I52-1 -> 0.081246005 | K53: =K52/J52-1 -> 0.070826181
B55: OpEx | D55: 798.462 | E55: ='Income Statement'!K19 -> 857.456 | F55: ='Income Statement'!P19 -> 917.1089 | G55: ='Income Statement'!U19 -> 1009.2924 | H55: ='Income Statement'!Z19 -> 1092.2441 | I55: ='Income Statement'!AE19 -> 1183.9257 | J55: ='Income Statement'!AJ19 -> 1270.5169 | K55: ='Income Statement'!AO19 -> 1362.5597
B56: % of sales | D56: =D55/D52 -> 0.74530255 | E56: =E55/E52 -> 0.7256405 | F56: =F55/F52 -> 0.70060966 | G56: =G55/G52 -> 0.67651047 | H56: =H55/H52 -> 0.6615102 | I56: =I55/I52 -> 0.65586753 | J56: =J55/J52 -> 0.65095 | K56: =K55/K52 -> 0.65193415
B58: EBIT | D58: =D52-D55 -> 272.864 | E58: =E52-E55 -> 324.198 | F58: =F52-F55 -> 391.90659 | G58: =G52-G55 -> 482.61708 | H58: =H52-H55 -> 558.8931 | I58: =I52-I55 -> 621.2036 | J58: =J52-J55 -> 681.2719 | K58: =K52-K55 -> 727.46688
...

Sheet Income Statement
A2: Planet Fitness Inc
A3: Income Statement
A4: (All values in $mn except EPS and stores) | AJ4: =AJ11/AE11-1 -> 0.081246005 | AO4: =AO11/AJ11-1 -> 0.070826181
B5: 2023A | F5: 2023A | G5: 2024A | K5: 2024A | L5: 2025E | P5: 2025 | Q5: =P5+1 -> 2026 | U5: =Q5 -> 2026 | V5: =U5+1 -> 2027 | Z5: =V5 -> 2027 | AA5: =Z5+1 -> 2028 | AE5: =AA5 -> 2028 | AF5: =AE5+1 -> 2029 | AJ5: =AF5 -> 2029 | AK5: =AJ5+1 -> 2030 | AO5: =AK5 -> 2030
B6: 1QA | C6: 2QA | D6: 3QA | E6: 4QA | F6: FY | G6: 1QA | H6: 2QA | I6: 3QA | J6: 4QE | K6: FY | L6: 1QA | M6: 2QA | N6: 3QA | O6: 4QE | P6: FY | Q6: 1QE | R6: 2QE | S6: 3QE | T6: 4QE | U6: FY | V6: 1QE | W6: 2QE | X6: 3QE | Y6: 4QE | Z6: FY | AA6: 1QE | AB6: 2QE | AC6: 3QE | AD6: 4QE | AE6: FY | AF6: 1QE | AG6: 2QE | AH6: 3QE | AI6: 4QE | AJ6: FY | AK6: 1QE | AL6: 2QE | AM6: 3QE | AN6: 4QE | AO6: FY
A7: Revenue:
A8: Franchise | B8: 75.878 | C8: 80.846 | D8: 80.587 | E8: 80.604 | F8: 387.927 | G8: 104.02 | H8: 107.79 | I8: 102.415 | J8: 109.022 | K8: =SUM(G8:J8) -> 423.247 | L8: 115.18 | M8: 119.658 | N8: 113.675 | O8: =Assumptions!O10 -> 119.70554 | P8: =SUM(L8:O8) -> 468.21854 | Q8: =Assumptions!Q10 -> 141.16781 | R8: =Assumptions!R10 -> 146.8498 | S8: =Assumptions!S10 -> 138.76409 | T8: =Assumptions!T10 -> 145.90974 | U8: =SUM(Q8:T8) -> 572.69144 | V8: =Assumptions!V10 -> 158.80701 | W8: =Assumptions!W10 -> 165.38773 | X8: =Assumptions!X10 -> 154.80182 | Y8: =Assumptions!Y10 -> 162.60189 | Z8: =SUM(V8:Y8) -> 641.59844 | AA8: =Assumptions!AA10 -> 175.92554 | AB8: =Assumptions!AB10 -> 183.11879 | AC8: =Assumptions!AC10 -> 171.30563 | AD8: =Assumptions!AD10 -> 179.73848 | AE8: =SUM(AA8:AD8) -> 710.08845 | AF8: =Assumptions!AF10 -> 192.342 | AG8: =Assumptions!AG10 -> 199.95215 | AH8: =Assumptions!AH10 -> 186.7566 | AI8: =Assumptions!AI10 -> 195.58029 | AJ8: =SUM(AF8:AI8) -> 774.63104 | AK8: =Assumptions!AK10 -> 209.04859 | AL8: =Assumptions!AL10 -> 217.24156 | AM8: =Assumptions!AM10 -> 202.8331 | AN8: =Assumptions!AN10 -> 212.24747 | AO8: =SUM(AK8:AN8) -> 841.37072
A9: Corporate-owned stores | B9: 105.882 | C9: 113.759 | D9: 113.245 | E9: 116.411 | F9: 449.297 | G9: 122.378 | H9: 125.466 | I9: 128.132 | J9: 126.311 | K9: =SUM(G9:J9) -> 502.287 | L9: 133.669 | M9: 138.989 | N9: 137.833 | O9: =Assumptions!O14 -> 136.30695 | P9: =SUM(L9:O9) -> 546.79795 | Q9: =Assumptions!Q14 -> 146.14797 | R9: =Assumptions!R14 -> 151.12276 | S9: =Assumptions!S14 -> 151.39635 | T9: =Assumptions!T14 -> 151.14316 | U9: =SUM(Q9:T9) -> 599.81025 | V9: =Assumptions!V14 -> 161.94077 | W9: =Assumptions!W14 -> 168.48763 | X9: =Assumptions!X14 -> 169.47154 | Y9: =Assumptions!Y14 -> 169.46958 | Z9: =SUM(V9:Y9) -> 669.36952 | AA9: =Assumptions!AA14 -> 179.60022 | AB9: =Assumptions!AB14 -> 186.72059 | AC9: =Assumptions!AC14 -> 187.61465 | AD9: =Assumptions!AD14 -> 187.32937 | AE9: =SUM(AA9:AD9) -> 741.26483 | AF9: =Assumptions!AF14 -> 198.29744 | AG9: =Assumptions!AG14 -> 205.73328 | AH9: =Assumptions!AH14 -> 205.95842 | AI9: =Assumptions!AI14 -> 204.54822 | AJ9: =SUM(AF9:AI9) -> 814.53737 | AK9: =Assumptions!AK14 -> 213.66338 | AL9: =Assumptions!AL14 -> 221.58403 | AM9: =Assumptions!AM14 -> 221.70691 | AN9: =Assumptions!AN14 -> 220.01561 | AO9: =SUM(AK9:AN9) -> 876.96993
A10: Equipment | B10: 23.661 | C10: 73.862 | D10: 66.141 | E10: 70.437 | F10: 234.101 | G10: 21.619 | H10: 67.685 | I10: 61.699 | J10: 105.117 | K10: =SUM(G10:J10) -> 256.12 | L10: 27.813 | M10: 82.232 | N10: 78.837 | O10: =Assumptions!O18 -> 105.117 | P10: =SUM(L10:O10) -> 293.999 | Q10: =Assumptions!Q18 -> 30.31617 | R10: =Assumptions!R18 -> 89.63288 | S10: =Assumptions!S18 -> 85.93233 | T10: =Assumptions!T18 -> 113.52636 | U10: =SUM(Q10:T10) -> 319.40774 | V10: =Assumptions!V18 -> 32.286721 | W10: =Assumptions!W18 -> 95.459017 | X10: =Assumptions!X18 -> 91.517931 | Y10: =Assumptions!Y18 -> 120.90557 | Z10: =SUM(V10:Y10) -> 340.16924 | AA10: =Assumptions!AA18 -> 33.57819 | AB10: =Assumptions!AB18 -> 99.277378 | AC10: =Assumptions!AC18 -> 95.178649 | AD10: =Assumptions!AD18 -> 125.7418 | AE10: =SUM(AA10:AD10) -> 353.77601 | AF10: =Assumptions!AF18 -> 34.417645 | AG10: =Assumptions!AG18 -> 101.75931 | AH10: =Assumptions!AH18 -> 97.558115 | AI10: =Assumptions!AI18 -> 128.88534 | AJ10: =SUM(AF10:AI10) -> 362.62041 | AK10: =Assumptions!AK18 -> 35.278086 | AL10: =Assumptions!AL18 -> 104.3033 | AM10: =Assumptions!AM18 -> 99.997068 | AN10: =Assumptions!AN18 -> 132.10747 | AO10: =SUM(AK10:AN10) -> 371.68592
A11: Total revenue | B11: =SUM(B8:B10) -> 205.421 | C11: =SUM(C8:C10) -> 268.467 | D11: =SUM(D8:D10) -> 259.973 | E11: =SUM(E8:E10) -> 267.452 | F11: =SUM(F8:F10) -> 1071.325 | G11: =SUM(G8:G10) -> 248.017 | H11: =SUM(H8:H10) -> 300.941 | I11: =SUM(I8:I10) -> 292.246 | ... AO11: =SUM(AO8:AO10) -> 2090.0266
A12: Operating costs and expenses:
A13: Cost of revenue | B13: 19.354 | C13: 59.457 | D13: 53.751 | E13: 57.465 | F13: 190.027 | G13: 18.993 | H13: 51.934 | I13: 45.701 | J13: 80.494 | K13: =SUM(G13:J13) -> 197.122 | L13: 22.485 | M13: 59.423 | N13: 58.155 | O13: =Assumptions!O96 -> 85.383339 | P13: =SUM(L13:O13) -> 225.44634 | Q13: =Assumptions!Q96 -> 23.908937 | R13: =Assumptions!R96 -> 65.242854 | S13: =Assumptions!S96 -> 63.95203 | T13: =Assumptions!T96 -> 94.611475 | U13: =SUM(Q13:T13) -> 247.7153 | V13: =Assumptions!V96 -> 24.808601 | W13: =Assumptions!W96 -> 70.120115 | X13: =Assumptions!X96 -> 68.623537 | Y13: =Assumptions!Y96 -> 102.11649 | Z13: =SUM(V13:Y13) -> 265.66874 | AA13: =Assumptions!AA96 -> 27.34329 | AB13: =Assumptions!AB96 -> 76.617488 | AC13: =Assumptions!AC96 -> 74.945952 | AD13: =Assumptions!AD96 -> 111.09612 | AE13: =SUM(AA13:AD13) -> 290.00285 | AF13: =Assumptions!AF96 -> 29.869806 | AG13: =Assumptions!AG96 -> 82.877324 | AH13: =Assumptions!AH96 -> 80.916261 | AI13: =Assumptions!AI96 -> 119.25778 | AJ13: =SUM(AF13:AI13) -> 312.92117 | AK13: =Assumptions!AK96 -> 32.184086 | AL13: =Assumptions!AL96 -> 88.705361 | AM13: =Assumptions!AM96 -> 86.571294 | AN13: =Assumptions!AN96 -> 127.22838 | AO13: =SUM(AK13:AN13) -> 334.68912
A14: Store operations | B14: 66.015 | C14: 58.876 | D14: 63.12 | E14: 65.608 | F14: 253.619 | G14: 74.353 | H14: 70.152 | I14: 71.614 | J14: 74.388 | K14: =SUM(G14:J14) -> 290.507 | L14: 81.68 | M14: 77.437 | N14: 79.792 | O14: =Assumptions!O100 -> 77.642842 | P14: =SUM(L14:O14) -> 316.55184 | Q14: =Assumptions!Q100 -> 91.869927 | R14: =Assumptions!R100 -> 85.726147 | S14: =Assumptions!S100 -> 88.585427 | T14: =Assumptions!T100 -> 85.811065 | U14: =SUM(Q14:T14) -> 351.99257 | V14: =Assumptions!V100 -> 100.34437 | W14: =Assumptions!W100 -> 94.955275 | X14: =Assumptions!X100 -> 97.936071 | Y14: =Assumptions!Y100 -> 94.672202 | Z14: =SUM(V14:Y14) -> 387.90792 | AA14: =Assumptions!AA100 -> 110.59653 | AB14: =Assumptions!AB100 -> 103.75389 | AC14: =Assumptions!AC100 -> 106.95911 | AD14: =Assumptions!AD100 -> 102.99722 | AE14: =SUM(AA14:AD14) -> 424.30674 | AF14: =Assumptions!AF100 -> 120.81563 | AG14: =Assumptions!AG100 -> 112.23084 | AH14: =Assumptions!AH100 -> 115.47963 | AI14: =Assumptions!AI100 -> 110.56389 | AJ14: =SUM(AF14:AI14) -> 459.09 | AK14: =Assumptions!AK100 -> 130.1763 | AL14: =Assumptions!AL100 -> 120.12305 | AM14: =Assumptions!AM100 -> 123.55021 | AN14: =Assumptions!AN100 -> 117.95344 | AO14: =SUM(AK14:AN14) -> 491.803
A15: Selling, general and administrative | B15: 27.767 | C15: 32.646 | D15: 33.29 | E15: 31.225 | F15: 124.928 | G15: 29.193 | H15: 31.613 | I15: 32.647 | J15: 35.693 | K15: =SUM(G15:J15) -> 129.146 | L15: 34.307 | M15: 35.511 | N15: 30.525 | O15: =Assumptions!O104 -> 35.390691 | P15: =SUM(L15:O15) -> 135.73369 | Q15: =Assumptions!Q104 -> 39.387409 | R15: =Assumptions!R104 -> 40.378717 | S15: =Assumptions!S104 -> 34.75225 | T15: =Assumptions!T104 -> 40.236768 | U15: =SUM(Q15:T15) -> 154.75514 | V15: =Assumptions!V104 -> 43.777442 | W15: =Assumptions!W104 -> 44.72582 | X15: =Assumptions!X104 -> 38.420527 | Y15: =Assumptions!Y104 -> 44.39175 | Z15: =SUM(V15:Y15) -> 171.31554 | AA15: =Assumptions!AA104 -> 48.250172 | AB15: =Assumptions!AB104 -> 48.870142 | AC15: =Assumptions!AC104 -> 41.960283 | AD15: =Assumptions!AD104 -> 48.295346 | AE15: =SUM(AA15:AD15) -> 187.37594 | AF15: =Assumptions!AF104 -> 44.205938 | AG15: =Assumptions!AG104 -> 52.774254 | AH15: =Assumptions!AH104 -> 50.988406 | AI15: =Assumptions!AI104 -> 55.017441 | AJ15: =SUM(AF15:AI15) -> 202.98604 | AK15: =Assumptions!AK104 -> 47.630966 | AL15: =Assumptions!AL104 -> 56.485405 | AM15: =Assumptions!AM104 -> 54.551857 | AN15: =Assumptions!AN104 -> 58.694537 | AO15: =SUM(AK15:AN15) -> 217.36276
A16: National advertising fund expense | B16: 16.987 | C16: 17.89 | D16: 17.618 | E16: 17.599 | F16: 70.094 | G16: 19.792 | H16: 20.112 | I16: 19.72 | J16: 19.385 | K16: =SUM(G16:J16) -> 79.009 | L16: 21.944 | M16: 22.777 | N16: 21.429 | O16: =Assumptions!O108 -> 20.35425 | P16: =SUM(L16:O16) -> 86.50425 | Q16: =Assumptions!Q108 -> 27.43 | R16: =Assumptions!R108 -> 28.47125 | S16: =Assumptions!S108 -> 26.78625 | T16: =Assumptions!T108 -> 25.442812 | U16: =SUM(Q16:T16) -> 108.13031 | V16: =Assumptions!V108 -> 29.3501 | W16: =Assumptions!W108 -> 30.464237 | X16: =Assumptions!X108 -> 28.661288 | Y16: =Assumptions!Y108 -> 27.223809 | Z16: =SUM(V16:Y16) -> 115.69943 | AA16: =Assumptions!AA108 -> 30.817605 | AB16: =Assumptions!AB108 -> 31.987449 | AC16: =Assumptions!AC108 -> 30.094352 | AD16: =Assumptions!AD108 -> 28.585 | AE16: =SUM(AA16:AD16) -> 121.48441 | AF16: =Assumptions!AF108 -> 32.358485 | AG16: =Assumptions!AG108 -> 33.586822 | AH16: =Assumptions!AH108 -> 31.599069 | AI16: =Assumptions!AI108 -> 30.01425 | AJ16: =SUM(AF16:AI16) -> 127.55863 | AK16: =Assumptions!AK108 -> 33.97641 | AL16: =Assumptions!AL108 -> 35.266163 | AM16: =Assumptions!AM108 -> 33.179023 | AN16: =Assumptions!AN108 -> 31.514962 | AO16: =SUM(AK16:AN16) -> 133.93656
A17: Depreciation and amortization | B17: 36.01 | C17: 36.767 | D17: 37.477 | E17: 39.159 | F17: 149.413 | G17: 39.38 | H17: 39.817 | I17: 41.033 | J17: 40.116 | K17: =SUM(G17:J17) -> 160.346 | L17: 38.281 | M17: 38.429 | N17: 39.108 | O17: =-Assumptions!O122-Assumptions!O137 -> 39.123781 | P17: =SUM(L17:O17) -> 154.94178 | Q17: =-Assumptions!Q122-Assumptions!Q137 -> 35.633367 | R17: =-Assumptions!R122-Assumptions!R137 -> 35.966672 | S17: =-Assumptions!S122-Assumptions!S137 -> 36.943464 | T17: =-Assumptions!T122-Assumptions!T137 -> 38.155528 | U17: =SUM(Q17:T17) -> 146.69903 | V17: =-Assumptions!V122-Assumptions!V137 -> 37.793067 | W17: =-Assumptions!W122-Assumptions!W137 -> 38.250358 | X17: =-Assumptions!X122-Assumptions!X137 -> 35.958162 | Y17: =-Assumptions!Y122-Assumptions!Y137 -> 39.650888 | Z17: =SUM(V17:Y17) -> 151.65247 | AA17: =-Assumptions!AA122-Assumptions!AA137 -> 40.006207 | AB17: =-Assumptions!AB122-Assumptions!AB137 -> 40.541347 | AC17: =-Assumptions!AC122-Assumptions!AC137 -> 38.098447 | AD17: =-Assumptions!AD122-Assumptions!AD137 -> 42.10975 | AE17: =SUM(AA17:AD17) -> 160.75575 | AF17: =-Assumptions!AF122-Assumptions!AF137 -> 41.786972 | AG17: =-Assumptions!AG122-Assumptions!AG137 -> 42.3786 | AH17: =-Assumptions!AH122-Assumptions!AH137 -> 39.735371 | AI17: =-Assumptions!AI122-Assumptions!AI137 -> 44.060158 | AJ17: =SUM(AF17:AI17) -> 167.9611 | AK17: =-Assumptions!AK122-Assumptions!AK137 -> 46.006641 | AL17: =-Assumptions!AL122-Assumptions!AL137 -> 46.628034 | AM17: =-Assumptions!AM122-Assumptions!AM137 -> 43.7483 | AN17: =-Assumptions!AN122-Assumptions!AN137 -> 48.385276 | AO17: =SUM(AK17:AN17) -> 184.76825
A18: Other (gain) loss | B18: 3.936 | C18: 3.825 | D18: -0.056 | E18: 2.674 | F18: 10.379 | G18: 0.484 | H18: -0.066 | I18: 0.28 | J18: 0.628 | K18: =SUM(G18:J18) -> 1.326 | L18: -1.237 | M18: 4.9 | N18: -5.732 | O18: =Assumptions!O111 -> 0 | P18: =SUM(L18:O18) -> -2.069 | Q18: =Assumptions!Q111 -> 0 | R18: =Assumptions!R111 -> 0 | S18: =Assumptions!S111 -> 0 | T18: =Assumptions!T111 -> 0 | U18: =SUM(Q18:T18) -> 0 | V18: =Assumptions!V111 -> 0 | W18: =Assumptions!W111 -> 0 | X18: =Assumptions!X111 -> 0 | Y18: =Assumptions!Y111 -> 0 | Z18: =SUM(V18:Y18) -> 0 | AA18: =Assumptions!AA111 -> 0 | AB18: =Assumptions!AB111 -> 0 | AC18: =Assumptions!AC111 -> 0 | AD18: =Assumptions!AD111 -> 0 | AE18: =SUM(AA18:AD18) -> 0 | AF18: =Assumptions!AF111 -> 0 | AG18: =Assumptions!AG111 -> 0 | AH18: =Assumptions!AH111 -> 0 | AI18: =Assumptions!AI111 -> 0 | AJ18: =SUM(AF18:AI18) -> 0 | AK18: =Assumptions!AK111 -> 0 | AL18: =Assumptions!AL111 -> 0 | AM18: =Assumptions!AM111 -> 0 | AN18: =Assumptions!AN111 -> 0 | AO18: =SUM(AK18:AN18) -> 0
A19: Total operating costs and expenses | B19: =SUM(B12:B18) -> 170.069 | C19: =SUM(C12:C18) -> 209.461 | D19: =SUM(D12:D18) -> 205.2 | E19: =SUM(E12:E18) -> 213.73 | F19: =SUM(F12:F18) -> 798.46 | G19: =SUM(G12:G18) -> 182.195 | H19: =SUM(H12:H18) -> 213.562 | I19: =SUM(I12:I18) -> 210.995 | ... AO19: =SUM(AO12:AO18) -> 1362.5597
A20: Income from operations | B20: =B11-B19 -> 35.352 | C20: =C11-C19 -> 59.006 | D20: =D11-D19 -> 54.773 | E20: =E11-E19 -> 53.722 | F20: =F11-F19 -> 272.865 | G20: =G11-G19 -> 65.822 | H20: =H11-H19 -> 87.379 | I20: =I11-I19 -> 81.251 | ... AO20: =AO11-AO19 -> 727.46688
A21: Other income (expense), net:
A22: Interest income | B22: 3.931 | C22: 4.163 | D22: 4.245 | E22: 5.402 | F22: 17.741 | G22: 5.461 | H22: 5.616 | I22: 5.61 | J22: 6.428 | K22: =SUM(G22:J22) -> 23.115 | L22: 5.812 | M22: 5.69 | N22: 5.936 | O22: =Assumptions!O152 -> 4.3729962 | P22: =SUM(L22:O22) -> 21.810996 | Q22: =Assumptions!Q152 -> 4.3997895 | R22: =Assumptions!R152 -> 5.5531461 | S22: =Assumptions!S152 -> 6.0778966 | T22: =Assumptions!T152 -> 6.3955222 | U22: =SUM(Q22:T22) -> 22.426354 | V22: =Assumptions!V152 -> 6.8113158 | W22: =Assumptions!W152 -> 8.1209775 | X22: =Assumptions!X152 -> 8.6953001 | Y22: =Assumptions!Y152 -> 9.1922914 | Z22: =SUM(V22:Y22) -> 32.819885 | AA22: =Assumptions!AA152 -> 9.7195021 | AB22: =Assumptions!AB152 -> 11.221024 | AC22: =Assumptions!AC152 -> 11.882822 | AD22: =Assumptions!AD152 -> 12.468632 | AE22: =SUM(AA22:AD22) -> 45.29198 | AF22: =Assumptions!AF152 -> 13.069652 | AG22: =Assumptions!AG152 -> 14.846825 | AH22: =Assumptions!AH152 -> 15.636341 | AI22: =Assumptions!AI152 -> 16.311401 | AJ22: =SUM(AF22:AI22) -> 59.86422 | AK22: =Assumptions!AK152 -> 17.009142 | AL22: =Assumptions!AL152 -> 18.965588 | AM22: =Assumptions!AM152 -> 19.845009 | AN22: =Assumptions!AN152 -> 20.60315 | AO22: =SUM(AK22:AN22) -> 76.42289
A23: Interest expense | B23: -21.599 | C23: -21.468 | D23: -21.704 | E23: -21.805 | F23: -86.576 | G23: -21.433 | H23: -24.533 | I23: -26.603 | J23: -27.468 | K23: =SUM(G23:J23) -> -100.037 | L23: -26.197 | M23: -26.181 | N23: -26.342 | O23: =-Assumptions!O151 -> -27.743262 | P23: =SUM(L23:O23) -> -106.46326 | Q23: =-Assumptions!Q151 -> -26.362049 | R23: =-Assumptions!R151 -> -26.362049 | S23: =-Assumptions!S151 -> -26.362049 | T23: =-Assumptions!T151 -> -26.362049 | U23: =SUM(Q23:T23) -> -105.4482 | V23: =-Assumptions!V151 -> -26.334104 | W23: =-Assumptions!W151 -> -26.278213 | X23: =-Assumptions!X151 -> -26.222322 | Y23: =-Assumptions!Y151 -> -26.166432 | Z23: =SUM(V23:Y23) -> -105.00107 | AA23: =-Assumptions!AA151 -> -26.110541 | AB23: =-Assumptions!AB151 -> -26.054651 | AC23: =-Assumptions!AC151 -> -25.99876 | AD23: =-Assumptions!AD151 -> -25.942869 | AE23: =SUM(AA23:AD23) -> -104.10682 | AF23: =-Assumptions!AF151 -> -25.914924 | AG23: =-Assumptions!AG151 -> -25.914924 | AH23: =-Assumptions!AH151 -> -25.914924 | AI23: =-Assumptions!AI151 -> -25.914924 | AJ23: =SUM(AF23:AI23) -> -103.6597 | AK23: =-Assumptions!AK151 -> -25.914924 | AL23: =-Assumptions!AL151 -> -25.914924 | AM23: =-Assumptions!AM151 -> -25.914924 | AN23: =-Assumptions!AN151 -> -25.914924 | AO23: =SUM(AK23:AN23) -> -103.6597
A24: Other income (expense), net | B24: 0.113 | C24: 0.37 | D24: 0.148 | E24: 2.881 | F24: 3.512 | G24: 0.647 | H24: 1.043 | I24: -0.558 | J24: -1.68 | K24: =SUM(G24:J24) -> -0.548 | L24: 0.283 | M24: 1.942 | N24: 1.067 | O24: =N24 -> 1.067 | P24: =SUM(L24:O24) -> 4.359 | Q24: =O24 -> 1.067 | R24: =Q24 -> 1.067 | S24: =R24 -> 1.067 | T24: =S24 -> 1.067 | U24: =SUM(Q24:T24) -> 4.268 | V24: =Q24 -> 1.067 | W24: =V24 -> 1.067 | X24: =W24 -> 1.067 | Y24: =X24 -> 1.067 | Z24: =SUM(V24:Y24) -> 4.268 | AA24: =Y24 -> 1.067 | AB24: =AA24 -> 1.067 | AC24: =AB24 -> 1.067 | AD24: =AC24 -> 1.067 | AE24: =SUM(AA24:AD24) -> 4.268 | AF24: =AD24 -> 1.067 | AG24: =AF24 -> 1.067 | AH24: =AG24 -> 1.067 | AI24: =AH24 -> 1.067 | AJ24: =SUM(AF24:AI24) -> 4.268 | AK24: =AI24 -> 1.067 | AL24: =AK24 -> 1.067 | AM24: =AL24 -> 1.067 | AN24: =AM24 -> 1.067 | AO24: =SUM(AK24:AN24) -> 4.268
A25: Total other expense, net | B25: =SUM(B22:B24) -> -17.555 | C25: =SUM(C22:C24) -> -16.935 | D25: =SUM(D22:D24) -> -17.311 | E25: =SUM(E22:E24) -> -13.522 | F25: =SUM(F22:F24) -> -65.323 | G25: =SUM(G22:G24) -> -15.325 | H25: =SUM(H22:H24) -> -17.874 | I25: =SUM(I22:I24) -> -21.551 | ... AO25: =SUM(AO22:AO24) -> -22.968806
A27: Income before income taxes | B27: =B20+B25 -> 17.797 | C27: =C20+C25 -> 42.071 | D27: =D20+D25 -> 37.462 | E27: =E20+E25 -> 40.2 | F27: =F20+F25 -> 207.542 | G27: =G20+G25 -> 50.497 | H27: =H20+H25 -> 69.505 | I27: =I20+I25 -> 59.7 | ... AO27: =AO20+AO25 -> 704.49808
A28: Provision for income taxes | B28: 9.567 | C28: 15.814 | D28: 13.474 | E28: 19.657 | F28: 58.512 | G28: 14.324 | H28: 18.977 | I28: 16.523 | J28: 18.619 | K28: =SUM(G28:J28) -> 68.443 | L28: 16.216 | M28: 24.93 | N28: 27.974 | O28: =O27*Assumptions!O157 -> 22.417978 | P28: =SUM(L28:O28) -> 91.537978 | Q28: =Q27*Assumptions!Q157 -> 22.060482 | R28: =R27*Assumptions!R157 -> 31.493889 | S28: =S27*Assumptions!S157 -> 29.745594 | T28: =T27*Assumptions!T157 -> 30.185606 | U28: =SUM(Q28:T28) -> 113.48557 | V28: =V27*Assumptions!V157 -> 27.679942 | W28: =W27*Assumptions!W157 -> 37.577661 | X28: =X27*Assumptions!X157 -> 36.454603 | Y28: =Y27*Assumptions!Y157 -> 36.25315 | Z28: =SUM(V28:Y28) -> 137.96536 | AA28: =AA27*Assumptions!AA157 -> 32.811275 | AB28: =AB27*Assumptions!AB157 -> 43.155928 | AC28: =AC27*Assumptions!AC157 -> 41.86671 | AD28: =AD27*Assumptions!AD157 -> 41.396635 | AE28: =SUM(AA28:AD28) -> 159.23055 | AF28: =AF27*Assumptions!AF157 -> 40.531998 | AG28: =AG27*Assumptions!AG157 -> 48.780423 | AH28: =AH27*Assumptions!AH157 -> 45.618332 | AI28: =AI27*Assumptions!AI157 -> 45.39943 | AJ28: =SUM(AF28:AI28) -> 180.33018 | AK28: =AK27*Assumptions!AK157 -> 45.009701 | AL28: =AL27*Assumptions!AL157 -> 53.400831 | AM28: =AM27*Assumptions!AM157 -> 49.99931 | AN28: =AN27*Assumptions!AN157 -> 49.554117 | AO28: =SUM(AK28:AN28) -> 197.96396
A29: Losses from equity-method investments, net of tax | B29: -0.265 | C29: -0.073 | D29: -0.242 | E29: -1.414 | F29: -1.994 | G29: -1.2 | H29: -1.216 | I29: -0.782 | J29: -0.844 | K29: =SUM(G29:J29) -> -4.042 | L29: -0.805 | M29: -0.628 | N29: -0.572 | O29: 0 | P29: =SUM(L29:O29) -> -2.005 | Q29: 0 | R29: 0 | S29: 0 | T29: 0 | U29: =SUM(Q29:T29) -> 0 | V29: 0 | W29: 0 | X29: 0 | Y29: 0 | Z29: =SUM(V29:Y29) -> 0 | AA29: 0 | AB29: 0 | AC29: 0 | AD29: 0 | AE29: =SUM(AA29:AD29) -> 0 | AF29: 0 | AG29: 0 | AH29: 0 | AI29: 0 | AJ29: =SUM(AF29:AI29) -> 0 | AK29: 0 | AL29: 0 | AM29: 0 | AN29: 0 | AO29: =SUM(AK29:AN29) -> 0
A30: Net income | B30: =B27-B28+B29 -> 7.965 | C30: =C27-C28+C29 -> 26.184 | D30: =D27-D28+D29 -> 23.746 | E30: =E27-E28+E29 -> 19.129 | F30: =F27-F28+F29 -> 147.036 | G30: =G27-G28+G29 -> 34.973 | H30: =H27-H28+H29 -> 49.312 | I30: =I27-I28+I29 -> 42.395 | ... AO30: =AO27-AO28+AO29 -> 506.53412
A32: Less net income attributable to non-controlling interests | B32: 2.064 | C32: 3.045 | D32: 2.19 | E32: 1.423 | F32: 8.722 | G32: 0.664 | H32: 0.672 | I32: 0.386 | J32: 0.479 | K32: =SUM(G32:J32) -> 2.201 | L32: 0.212 | M32: 0.276 | N32: 0.354 | O32: 0 | P32: =SUM(L32:O32) -> 0.842 | Q32: 0 | R32: 0 | S32: 0 | T32: 0 | U32: =SUM(Q32:T32) -> 0 | V32: 0 | W32: 0 | X32: 0 | Y32: 0 | Z32: =SUM(V32:Y32) -> 0 | AA32: 0 | AB32: 0 | AC32: 0 | AD32: 0 | AE32: =SUM(AA32:AD32) -> 0 | AF32: 0 | AG32: 0 | AH32: 0 | AI32: 0 | AJ32: =SUM(AF32:AI32) -> 0 | AK32: 0 | AL32: 0 | AM32: 0 | AN32: 0 | AO32: =SUM(AK32:AN32) -> 0
A33: Net income attributable to Planet Fitness, Inc. | B33: =B30-B32 -> 5.901 | C33: =C30-C32 -> 23.139 | D33: =D30-D32 -> 21.556 | E33: =E30-E32 -> 17.706 | F33: =SUM(B33:E33) -> 68.302 | G33: =G30-G32 -> 34.309 | H33: =H30-H32 -> 48.64 | I33: =I30-I32 -> 42.009 | J33: =J30-J32 -> 47.084 | K33: =SUM(G33:J33) -> 172.042 | L33: =L30-L32 -> 41.867 | M33: =M30-M32 -> 58.019 | N33: =N30-N32 -> 58.829 | O33: =O30-O32 -> 58.51335 | P33: =SUM(L33:O33) -> 217.22835 | Q33: =Q30-Q32 -> 56.446571 | R33: =R30-R32 -> 80.584008 | S33: =S30-S32 -> 76.110612 | T33: =T30-T32 -> 77.236479 | U33: =SUM(Q33:T33) -> 290.37767 | V33: =V30-V32 -> 70.82519 | W33: =W30-W32 -> 96.15067 | X33: =X30-X32 -> 93.277081 | Y33: =Y30-Y32 -> 92.761618 | Z33: =SUM(V33:Y33) -> 353.01456 | AA33: =AA30-AA32 -> 83.954829 | AB33: =AB30-AB32 -> 110.42389 | AC33: =AC30-AC32 -> 107.12514 | AD33: =AD30-AD32 -> 105.92235 | AE33: =SUM(AA33:AD33) -> 407.42621 | AF33: =AF30-AF32 -> 103.70999 | AG33: =AG30-AG32 -> 124.81539 | AH33: =AH30-AH32 -> 116.72449 | AI33: =AI30-AI32 -> 116.16438 | AJ33: =SUM(AF33:AI33) -> 461.41424 | AK33: =AK30-AK32 -> 115.16717 | AL33: =AL30-AL32 -> 136.63771 | AM33: =AM30-AM32 -> 127.93418 | AN33: =AN30-AN32 -> 126.79505 | AO33: =SUM(AK33:AN33) -> 506.53412
A34: Net income per share of Class A common stock:
A35: Basic | B35: =B33/B38 -> 0.069880631 | C35: =C33/C38 -> 0.27345246 | D35: =D33/D38 -> 0.25476894 | E35: =E33/E38 -> 0.206121 | F35: =F33/F38 -> 0.80453732 | G35: =G33/G38 -> 0.39476924 | H35: =H33/H38 -> 0.56031057 | I35: =I33/I38 -> 0.49673643 | ... AO35: =AO33/AO38 -> 6.0650421
A36: Diluted | B36: =B33/B39 -> 0.069597934 | C36: =C33/C39 -> 0.27251849 | D36: =D33/D39 -> 0.25394058 | E36: =E33/E39 -> 0.20542271 | F36: =F33/F39 -> 0.80180783 | G36: =G33/G39 -> 0.39335259 | H36: =H33/H39 -> 0.55936979 | I36: =I33/I39 -> 0.49581012 | ... AO36: =AO33/AO39 -> 6.0505527
A37: Weighted-average shares of Class A common stock outstanding:
A38: Basic | B38: 84.444 | C38: 84.618 | D38: 84.61 | E38: 85.901 | F38: 84.896 | G38: 86.909 | H38: 86.809 | I38: 84.57 | J38: 84.224 | K38: =AVERAGE(G38:J38) -> 85.628 | L38: 84.17 | M38: 83.861 | N38: 83.517 | O38: =N38 -> 83.517 | P38: =AVERAGE(L38:O38) -> 83.76625 | Q38: =N38 -> 83.517 | R38: =Q38 -> 83.517 | S38: =R38 -> 83.517 | T38: =S38 -> 83.517 | U38: =AVERAGE(Q38:T38) -> 83.517 | V38: =T38 -> 83.517 | W38: =V38 -> 83.517 | X38: =W38 -> 83.517 | Y38: =X38 -> 83.517 | Z38: =AVERAGE(V38:Y38) -> 83.517 | AA38: =V38 -> 83.517 | AB38: =AA38 -> 83.517 | AC38: =AB38 -> 83.517 | AD38: =AC38 -> 83.517 | AE38: =AVERAGE(AA38:AD38) -> 83.517 | AF38: =AA38 -> 83.517 | AG38: =AB38 -> 83.517 | AH38: =AC38 -> 83.517 | AI38: =AD38 -> 83.517 | AJ38: =AVERAGE(AF38:AI38) -> 83.517 | AK38: =AF38 -> 83.517 | AL38: =AG38 -> 83.517 | AM38: =AH38 -> 83.517 | AN38: =AI38 -> 83.517 | AO38: =AVERAGE(AK38:AN38) -> 83.517
A39: Diluted | B39: 84.787 | C39: 84.908 | D39: 84.886 | E39: 86.193 | F39: 85.185 | G39: 87.222 | H39: 86.955 | I39: 84.728 | J39: 84.442 | K39: =AVERAGE(G39:J39) -> 85.83675 | L39: 84.402 | M39: 84.065 | N39: 83.717 | O39: =N39-N38+O38 -> 83.717 | P39: =AVERAGE(L39:O39) -> 83.97525 | Q39: =O39-O38+Q38 -> 83.717 | R39: =Q39-Q38+R38 -> 83.717 | S39: =R39-R38+S38 -> 83.717 | T39: =S39-S38+T38 -> 83.717 | U39: =AVERAGE(Q39:T39) -> 83.717 | V39: =T39-T38+V38 -> 83.717 | W39: =V39-V38+W38 -> 83.717 | X39: =W39-W38+X38 -> 83.717 | Y39: =X39-X38+Y38 -> 83.717 | Z39: =AVERAGE(V39:Y39) -> 83.717 | AA39: =Y39-Y38+AA38 -> 83.717 | AB39: =AA39-AA38+AB38 -> 83.717 | AC39: =AB39-AB38+AC38 -> 83.717 | AD39: =AC39-AC38+AD38 -> 83.717 | AE39: =AVERAGE(AA39:AD39) -> 83.717 | AF39: =AD39-AD38+AF38 -> 83.717 | AG39: =AF39-AF38+AG38 -> 83.717 | AH39: =AG39-AG38+AH38 -> 83.717 | AI39: =AH39-AH38+AI38 -> 83.717 | AJ39: =AVERAGE(AF39:AI39) -> 83.717 | AK39: =AI39-AI38+AK38 -> 83.717 | AL39: =AK39-AK38+AL38 -> 83.717 | AM39: =AL39-AL38+AM38 -> 83.717 | AN39: =AM39-AM38+AN38 -> 83.717 | AO39: =AVERAGE(AK39:AN39) -> 83.717
A41: Non-GAAP measures
A42: Net Income (GAAP) | B42: =B30 -> 7.965 | C42: =C30 -> 26.184 | D42: =D30 -> 23.746 | E42: =E30 -> 19.129 | F42: =F30 -> 147.036 | G42: =G30 -> 34.973 | H42: =H30 -> 49.312 | I42: =I30 -> 42.395 | J42: =J30 -> 47.563 | K42: =SUM(G42:J42) -> 174.243 | L42: =L30 -> 42.079 | M42: =M30 -> 58.295 | N42: =N30 -> 59.183 | O42: =O30 -> 58.51335 | P42: =SUM(L42:O42) -> 218.07035 | Q42: =Q30 -> 56.446571 | R42: =R30 -> 80.584008 | S42: =S30 -> 76.110612 | T42: =T30 -> 77.236479 | U42: =SUM(Q42:T42) -> 290.37767 | V42: =V30 -> 70.82519 | W42: =W30 -> 96.15067 | X42: =X30 -> 93.277081 | Y42: =Y30 -> 92.761618 | Z42: =SUM(V42:Y42) -> 353.01456 | AA42: =AA30 -> 83.954829 | AB42: =AB30 -> 110.42389 | AC42: =AC30 -> 107.12514 | AD42: =AD30 -> 105.92235 | AE42: =SUM(AA42:AD42) -> 407.42621 | AF42: =AF30 -> 103.70999 | AG42: =AG30 -> 124.81539 | AH42: =AH30 -> 116.72449 | AI42: =AI30 -> 116.16438 | AJ42: =SUM(AF42:AI42) -> 461.41424 | AK42: =AK30 -> 115.16717 | AL42: =AL30 -> 136.63771 | AM42: =AM30 -> 127.93418 | AN42: =AN30 -> 126.79505 | AO42: =SUM(AK42:AN42) -> 506.53412
A43: Interest income | B43: =-B22 -> -3.931 | C43: =-C22 -> -4.163 | D43: =-D22 -> -4.245 | E43: =-E22 -> -5.402 | F43: =-F22 -> -17.741 | G43: =-G22 -> -5.461 | H43: =-H22 -> -5.616 | I43: =-I22 -> -5.61 | J43: =-J22 -> -6.428 | K43: =SUM(G43:J43) -> -23.115 | L43: =-L22 -> -5.812 | M43: =-M22 -> -5.69 | N43: =-N22 -> -5.936 | O43: =-O22 -> -4.3729962 | P43: =SUM(L43:O43) -> -21.810996 | Q43: =-Q22 -> -4.3997895 | R43: =-R22 -> -5.5531461 | S43: =-S22 -> -6.0778966 | T43: =-T22 -> -6.3955222 | U43: =SUM(Q43:T43) -> -22.426354 | V43: =-V22 -> -6.8113158 | W43: =-W22 -> -8.1209775 | X43: =-X22 -> -8.6953001 | Y43: =-Y22 -> -9.1922914 | Z43: =SUM(V43:Y43) -> -32.819885 | AA43: =-AA22 -> -9.7195021 | AB43: =-AB22 -> -11.221024 | AC43: =-AC22 -> -11.882822 | AD43: =-AD22 -> -12.468632 | AE43: =SUM(AA43:AD43) -> -45.29198 | AF43: =-AF22 -> -13.069652 | AG43: =-AG22 -> -14.846825 | AH43: =-AH22 -> -15.636341 | AI43: =-AI22 -> -16.311401 | AJ43: =SUM(AF43:AI43) -> -59.86422 | AK43: =-AK22 -> -17.009142 | AL43: =-AL22 -> -18.965588 | AM43: =-AM22 -> -19.845009 | AN43: =-AN22 -> -20.60315 | AO43: =SUM(AK43:AN43) -> -76.42289
A44: Interest expense | B44: =-B23 -> 21.599 | C44: =-C23 -> 21.468 | D44: =-D23 -> 21.704 | E44: =-E23 -> 21.805 | F44: =-F23 -> 86.576 | G44: =-G23 -> 21.433 | H44: =-H23 -> 24.533 | I44: =-I23 -> 26.603 | J44: =-J23 -> 27.468 | K44: =SUM(G44:J44) -> 100.037 | L44: =-L23 -> 26.197 | M44: =-M23 -> 26.181 | N44: =-N23 -> 26.342 | O44: =-O23 -> 27.743262 | P44: =SUM(L44:O44) -> 106.46326 | Q44: =-Q23 -> 26.362049 | R44: =-R23 -> 26.362049 | S44: =-S23 -> 26.362049 | T44: =-T23 -> 26.362049 | U44: =SUM(Q44:T44) -> 105.4482 | V44: =-V23 -> 26.334104 | W44: =-W23 -> 26.278213 | X44: =-X23 -> 26.222322 | Y44: =-Y23 -> 26.166432 | Z44: =SUM(V44:Y44) -> 105.00107 | AA44: =-AA23 -> 26.110541 | AB44: =-AB23 -> 26.054651 | AC44: =-AC23 -> 25.99876 | AD44: =-AD23 -> 25.942869 | AE44: =SUM(AA44:AD44) -> 104.10682 | AF44: =-AF23 -> 25.914924 | AG44: =-AG23 -> 25.914924 | AH44: =-AH23 -> 25.914924 | AI44: =-AI23 -> 25.914924 | AJ44: =SUM(AF44:AI44) -> 103.6597 | AK44: =-AK23 -> 25.914924 | AL44: =-AL23 -> 25.914924 | AM44: =-AM23 -> 25.914924 | AN44: =-AN23 -> 25.914924 | AO44: =SUM(AK44:AN44) -> 103.6597
...

Sheet Assumptions
A2: Planet Fitness Inc
A3: Assumptions
A4: (All values in $mn except EPS and stores)
B5: 2023A | F5: 2023A | G5: 2024A | K5: 2024A | L5: 2025E | P5: 2025 | Q5: =P5+1 -> 2026 | U5: =Q5 -> 2026 | V5: =U5+1 -> 2027 | Z5: =V5 -> 2027 | AA5: =Z5+1 -> 2028 | AE5: =AA5 -> 2028 | AF5: =AE5+1 -> 2029 | AJ5: =AF5 -> 2029 | AK5: =AJ5+1 -> 2030 | AO5: =AK5 -> 2030
B6: 1QA | C6: 2QA | D6: 3QA | E6: 4QA | F6: FY | G6: 1QA | H6: 2QA | I6: 3QA | J6: 4QA | K6: FY | L6: 1QA | M6: 2QA | N6: 3QA | O6: 4QE | P6: FY | Q6: 1QE | R6: 2QE | S6: 3QE | T6: 4QE | U6: FY | V6: 1QE | W6: 2QE | X6: 3QE | Y6: 4QE | Z6: FY | AA6: 1QE | AB6: 2QE | AC6: 3QE | AD6: 4QE | AE6: FY | AF6: 1QE | AG6: 2QE | AH6: 3QE | AI6: 4QE | AJ6: FY | AK6: 1QE | AL6: 2QE | AM6: 3QE | AN6: 4QE | AO6: FY
A8: Revenue Breakdown: | T8: =U10-U8 -> 44.435497 | U8: 528.25594
A10: Franchise segment total | B10: 92.682 | C10: 98.842 | D10: 98.165 | E10: 98.24 | F10: =SUM(B10:E10) -> 387.929 | G10: 104.02 | H10: 107.79 | I10: 102.415 | J10: 109.022 | K10: =SUM(G10:J10) -> 423.247 | L10: ='Income Statement'!L114 -> 115.18 | M10: ='Income Statement'!M114 -> 119.658 | N10: ='Income Statement'!N114 -> 113.675 | O10: =O61*AVERAGE(O52,O58) -> 119.70554 | P10: =SUM(L10:O10) -> 468.21854 | Q10: =Q61*AVERAGE(Q52,Q58) -> 141.16781 | R10: =R61*AVERAGE(R52,R58) -> 146.8498 | S10: =S61*AVERAGE(S52,S58) -> 138.76409 | T10: =T61*AVERAGE(T52,T58) -> 145.90974 | U10: =SUM(Q10:T10) -> 572.69144 | V10: =V61*AVERAGE(V52,V58) -> 158.80701 | W10: =W61*AVERAGE(W52,W58) -> 165.38773 | X10: =X61*AVERAGE(X52,X58) -> 154.80182 | Y10: =Y61*AVERAGE(Y52,Y58) -> 162.60189 | Z10: =SUM(V10:Y10) -> 641.59844 | AA10: =AA61*AVERAGE(AA52,AA58) -> 175.92554 | AB10: =AB61*AVERAGE(AB52,AB58) -> 183.11879 | AC10: =AC61*AVERAGE(AC52,AC58) -> 171.30563 | AD10: =AD61*AVERAGE(AD52,AD58) -> 179.73848 | AE10: =SUM(AA10:AD10) -> 710.08845 | AF10: =AF61*AVERAGE(AF52,AF58) -> 192.342 | AG10: =AG61*AVERAGE(AG52,AG58) -> 199.95215 | AH10: =AH61*AVERAGE(AH52,AH58) -> 186.7566 | AI10: =AI61*AVERAGE(AI52,AI58) -> 195.58029 | AJ10: =SUM(AF10:AI10) -> 774.63104 | AK10: =AK61*AVERAGE(AK52,AK58) -> 209.04859 | AL10: =AL61*AVERAGE(AL52,AL58) -> 217.24156 | AM10: =AM61*AVERAGE(AM52,AM58) -> 202.8331 | AN10: =AN61*AVERAGE(AN52,AN58) -> 212.24747 | AO10: =SUM(AK10:AN10) -> 841.37072
A11: YoY % Change | G11: =IFERROR(G10/B10-1,"na") -> 0.12233228 | H11: =IFERROR(H10/C10-1,"na") -> 0.090528318 | I11: =IFERROR(I10/D10-1,"na") -> 0.043294453 | J11: =IFERROR(J10/E10-1,"na") -> 0.10975163 | K11: =IFERROR(K10/F10-1,"na") -> 0.091042433 | L11: =IFERROR(L10/G10-1,"na") -> 0.10728706 | M11: =IFERROR(M10/H10-1,"na") -> 0.11010298 | N11: =IFERROR(N10/I10-1,"na") -> 0.10994483 | ... AO11: =IFERROR(AO10/AJ10-1,"na") -> 0.086156731
A12: As % of Total Revenue | B12: =B10/B$22 -> 0.41706379 | C12: =C10/C$22 -> 0.34504282 | D12: =D10/D$22 -> 0.35368275 | E12: =E10/E$22 -> 0.34459656 | F12: =F10/F$22 -> 0.36210173 | G12: =G10/G$22 -> 0.41940673 | H12: =H10/H$22 -> 0.35817652 | I12: =I10/I$22 -> 0.35044107 | ... AO12: =AO10/AO$22 -> 0.4025646
A14: Corporate-owned stores segment total | B14: 105.882 | C14: 113.759 | D14: 113.245 | E14: 116.41 | F14: =SUM(B14:E14) -> 449.296 | G14: 122.378 | H14: 125.466 | I14: 128.132 | J14: 126.311 | K14: =SUM(G14:J14) -> 502.287 | L14: 133.669 | M14: ='Income Statement'!M117 -> 138.989 | N14: ='Income Statement'!N117 -> 137.833 | O14: =O75*AVERAGE(O66,O72) -> 136.30695 | P14: =SUM(L14:O14) -> 546.79795 | Q14: =Q75*AVERAGE(Q66,Q72) -> 146.14797 | R14: =R75*AVERAGE(R66,R72) -> 151.12276 | S14: =S75*AVERAGE(S66,S72) -> 151.39635 | T14: =T75*AVERAGE(T66,T72) -> 151.14316 | U14: =SUM(Q14:T14) -> 599.81025 | V14: =V75*AVERAGE(V66,V72) -> 161.94077 | W14: =W75*AVERAGE(W66,W72) -> 168.48763 | X14: =X75*AVERAGE(X66,X72) -> 169.47154 | Y14: =Y75*AVERAGE(Y66,Y72) -> 169.46958 | Z14: =SUM(V14:Y14) -> 669.36952 | AA14: =AA75*AVERAGE(AA66,AA72) -> 179.60022 | AB14: =AB75*AVERAGE(AB66,AB72) -> 186.72059 | AC14: =AC75*AVERAGE(AC66,AC72) -> 187.61465 | AD14: =AD75*AVERAGE(AD66,AD72) -> 187.32937 | AE14: =SUM(AA14:AD14) -> 741.26483 | AF14: =AF75*AVERAGE(AF66,AF72) -> 198.29744 | AG14: =AG75*AVERAGE(AG66,AG72) -> 205.73328 | AH14: =AH75*AVERAGE(AH66,AH72) -> 205.95842 | AI14: =AI75*AVERAGE(AI66,AI72) -> 204.54822 | AJ14: =SUM(AF14:AI14) -> 814.53737 | AK14: =AK75*AVERAGE(AK66,AK72) -> 213.66338 | AL14: =AL75*AVERAGE(AL66,AL72) -> 221.58403 | AM14: =AM75*AVERAGE(AM66,AM72) -> 221.70691 | AN14: =AN75*AVERAGE(AN66,AN72) -> 220.01561 | AO14: =SUM(AK14:AN14) -> 876.96993
A15: YoY % Change | G15: =IFERROR(G14/B14-1,"na") -> 0.15579607 | H15: =IFERROR(H14/C14-1,"na") -> 0.10291054 | I15: =IFERROR(I14/D14-1,"na") -> 0.13145834 | J15: =IFERROR(J14/E14-1,"na") -> 0.085052831 | K15: =IFERROR(K14/F14-1,"na") -> 0.11794229 | L15: =IFERROR(L14/G14-1,"na") -> 0.092263315 | M15: =IFERROR(M14/H14-1,"na") -> 0.10778219 | N15: =IFERROR(N14/I14-1,"na") -> 0.075710986 | ... AO15: =IFERROR(AO14/AJ14-1,"na") -> 0.076647877
A16: As % of Total Revenue | B16: =B14/B$22 -> 0.47646304 | C16: =C14/C$22 -> 0.39711586 | D16: =D14/D$22 -> 0.4080151 | E16: =E14/E$22 -> 0.40833149 | F16: =F14/F$22 -> 0.41938308 | G16: =G14/G$22 -> 0.49342585 | H16: =H14/H$22 -> 0.41691229 | I16: =I14/I$22 -> 0.43843885 | ... AO16: =AO14/AO$22 -> 0.4195975
A18: Equipment segment total | B18: 23.661 | C18: 73.862 | D18: 66.141 | E18: 70.437 | F18: =SUM(B18:E18) -> 234.101 | G18: 21.619 | H18: 67.685 | I18: 61.699 | J18: 105.117 | K18: =SUM(G18:J18) -> 256.12 | L18: 27.813 | M18: ='Income Statement'!M120 -> 82.232 | N18: ='Income Statement'!N120 -> 78.837 | O18: =J18*(1+O19) -> 105.117 | P18: =SUM(L18:O18) -> 293.999 | Q18: =L18*(1+Q19) -> 30.31617 | R18: =M18*(1+R19) -> 89.63288 | S18: =N18*(1+S19) -> 85.93233 | T18: =O18*(1+T19) -> 113.52636 | U18: =SUM(Q18:T18) -> 319.40774 | V18: =Q18*(1+V19) -> 32.286721 | W18: =R18*(1+W19) -> 95.459017 | X18: =S18*(1+X19) -> 91.517931 | Y18: =T18*(1+Y19) -> 120.90557 | Z18: =SUM(V18:Y18) -> 340.16924 | AA18: =V18*(1+AA19) -> 33.57819 | AB18: =W18*(1+AB19) -> 99.277378 | AC18: =X18*(1+AC19) -> 95.178649 | AD18: =Y18*(1+AD19) -> 125.7418 | AE18: =SUM(AA18:AD18) -> 353.77601 | AF18: =AA18*(1+AF19) -> 34.417645 | AG18: =AB18*(1+AG19) -> 101.75931 | AH18: =AC18*(1+AH19) -> 97.558115 | AI18: =AD18*(1+AI19) -> 128.88534 | AJ18: =SUM(AF18:AI18) -> 362.62041 | AK18: =AF18*(1+AK19) -> 35.278086 | AL18: =AG18*(1+AL19) -> 104.3033 | AM18: =AH18*(1+AM19) -> 99.997068 | AN18: =AI18*(1+AN19) -> 132.10747 | AO18: =SUM(AK18:AN18) -> 371.68592
A19: YoY % Change | F19: =IFERROR(F18/#REF!-1,"na") -> na | G19: =IFERROR(G18/B18-1,"na") -> -0.086302354 | H19: =IFERROR(H18/C18-1,"na") -> -0.08362893 | I19: =IFERROR(I18/D18-1,"na") -> -0.067159553 | J19: =IFERROR(J18/E18-1,"na") -> 0.49235487 | K19: =IFERROR(K18/F18-1,"na") -> 0.094057693 | L19: =IFERROR(L18/G18-1,"na") -> 0.28650724 | M19: =IFERROR(M18/H18-1,"na") -> 0.21492207 | N19: =IFERROR(N18/I18-1,"na") -> 0.27776787 | O19: 0 | P19: =IFERROR(P18/K18-1,"na") -> 0.14789552 | Q19: 0.09 | R19: 0.09 | S19: 0.09 | T19: 0.08 | U19: =IFERROR(U18/P18-1,"na") -> 0.08642458 | V19: 0.065 | W19: 0.065 | X19: 0.065 | Y19: 0.065 | Z19: =IFERROR(Z18/U18-1,"na") -> 0.065 | AA19: 0.04 | AB19: 0.04 | AC19: 0.04 | AD19: 0.04 | AE19: =IFERROR(AE18/Z18-1,"na") -> 0.04 | AF19: 0.025 | AG19: 0.025 | AH19: 0.025 | AI19: 0.025 | AJ19: =IFERROR(AJ18/AE18-1,"na") -> 0.025 | AK19: 0.025 | AL19: 0.025 | AM19: 0.025 | AN19: 0.025 | AO19: =IFERROR(AO18/AJ18-1,"na") -> 0.025
A20: As % of Total Revenue | B20: =B18/B$22 -> 0.10647317 | C20: =C18/C$22 -> 0.25784133 | D20: =D18/D$22 -> 0.23830215 | E20: =E18/E$22 -> 0.24707195 | F20: =F18/F$22 -> 0.21851519 | G20: =G18/G$22 -> 0.087167412 | H20: =H18/H$22 -> 0.2249112 | I20: =I18/I$22 -> 0.21112008 | ... AO20: =AO18/AO$22 -> 0.17783789
A22: Total Revenue | B22: =B10+B14+B18 -> 222.225 | C22: =C10+C14+C18 -> 286.463 | D22: =D10+D14+D18 -> 277.551 | E22: =E10+E14+E18 -> 285.087 | F22: =F10+F14+F18 -> 1071.326 | G22: =G10+G14+G18 -> 248.017 | H22: =H10+H14+H18 -> 300.941 | I22: =I10+I14+I18 -> 292.246 | ... AO22: =AO10+AO14+AO18 -> 2090.0266
A23: YoY % Change | F23: 0.12560406 | G23: =IFERROR(G22/B22-1,"na") -> 0.11606255 | H23: =IFERROR(H22/C22-1,"na") -> 0.050540558 | I23: =IFERROR(I22/D22-1,"na") -> 0.052945224 | J23: =IFERROR(J22/E22-1,"na") -> 0.19419686 | K23: =IFERROR(K22/F22-1,"na") -> 0.10298266 | L23: =IFERROR(L22/G22-1,"na") -> 0.11549612 | M23: =IFERROR(M22/H22-1,"na") -> 0.1327104 | N23: =IFERROR(N22/I22-1,"na") -> 0.1303662 | ... AO23: =IFERROR(AO22/AJ22-1,"na") -> 0.070826181
A25: Segment EBITDA Details:
A27: Franchise | B27: 64.735 | C27: 66.101 | D27: 67.583 | E27: 68.309 | F27: =SUM(B27:E27) -> 266.728 | G27: ='Income Statement'!G124 -> 76.138 | H27: ='Income Statement'!H124 -> 77.409 | I27: ='Income Statement'!I124 -> 72.758 | J27: ='Income Statement'!J124 -> 74.817 | K27: =SUM(G27:J27) -> 301.122 | L27: 84.865 | M27: ='Income Statement'!M124 -> 86.502 | N27: ='Income Statement'!N124 -> 82.367 | O27: =O30*'Income Statement'!O$47 -> 84.620971 | P27: =SUM(L27:O27) -> 338.35497 | Q27: =Q30*'Income Statement'!Q$47 -> 97.801173 | R27: =R30*'Income Statement'!R$47 -> 101.5734 | S27: =S30*'Income Statement'!S$47 -> 90.44247 | T27: =T30*'Income Statement'!T$47 -> 96.512234 | U27: =SUM(Q27:T27) -> 386.32928 | V27: =V30*'Income Statement'!V$47 -> 111.97043 | W27: =W30*'Income Statement'!W$47 -> 114.37581 | X27: =X30*'Income Statement'!X$47 -> 101.60779 | Y27: =Y30*'Income Statement'!Y$47 -> 108.228 | Z27: =SUM(V27:Y27) -> 436.18203 | AA27: =AA30*'Income Statement'!AA$47 -> 124.43237 | AB27: =AB30*'Income Statement'!AB$47 -> 125.69625 | AC27: =AC30*'Income Statement'!AC$47 -> 111.58427 | AD27: =AD30*'Income Statement'!AD$47 -> 118.29243 | AE27: =SUM(AA27:AD27) -> 480.00532 | AF27: =AF30*'Income Statement'!AF$47 -> 142.90779 | AG27: =AG30*'Income Statement'!AG$47 -> 136.57688 | AH27: =AH30*'Income Statement'!AH$47 -> 117.76809 | AI27: =AI30*'Income Statement'!AI$47 -> 125.47763 | AJ27: =SUM(AF27:AI27) -> 522.73039 | AK27: =AK30*'Income Statement'!AK$47 -> 154.55967 | AL27: =AL30*'Income Statement'!AL$47 -> 146.54657 | AM27: =AM30*'Income Statement'!AM$47 -> 126.30576 | AN27: =AN30*'Income Statement'!AN$47 -> 134.11695 | AO27: =SUM(AK27:AN27) -> 561.52895
A28: YoY % Change | B28: =IFERROR(B27/#REF!-1,"na") -> na | C28: =IFERROR(C27/#REF!-1,"na") -> na | D28: =IFERROR(D27/#REF!-1,"na") -> na | E28: =IFERROR(E27/#REF!-1,"na") -> na | F28: =IFERROR(F27/#REF!-1,"na") -> na | G28: =IFERROR(G27/B27-1,"na") -> 0.17614891 | H28: =IFERROR(H27/C27-1,"na") -> 0.17107154 | I28: =IFERROR(I27/D27-1,"na") -> 0.076572511 | J28: =IFERROR(J27/E27-1,"na") -> 0.095272951 | K28: =IFERROR(K27/F27-1,"na") -> 0.12894784 | L28: =IFERROR(L27/G27-1,"na") -> 0.11462082 | M28: =IFERROR(M27/H27-1,"na") -> 0.11746696 | N28: =IFERROR(N27/I27-1,"na") -> 0.13206795 | ... AO28: =IFERROR(AO27/AJ27-1,"na") -> 0.074222896
A29: Segment EBITDA Margin | B29: =B27/B$10 -> 0.69846356 | C29: =C27/C$10 -> 0.66875417 | D29: =D27/D$10 -> 0.6884633 | E29: =E27/E$10 -> 0.69532777 | F29: =F27/F$10 -> 0.68756912 | G29: =G27/G$10 -> 0.73195539 | H29: =H27/H$10 -> 0.7181464 | I29: =I27/I$10 -> 0.71042328 | ... AO29: =AO27/AO$10 -> 0.66739778
A30: As % of Total EBITDA | B30: =B27/B$47 -> 0.73550799 | C30: =C27/C$47 -> 0.57949783 | D30: =D27/D$47 -> 0.61588022 | E30: =E27/E$47 -> 0.60999982 | F30: =F27/F$47 -> 0.62937829 | G30: =G27/G$47 -> 0.71618177 | H30: =H27/H$47 -> 0.60940932 | I30: =I27/I$47 -> 0.6015842 | ... N30: =N27/N$47 -> 0.56157659 | O30: 0.59 | P30: =P27/P$47 -> 0.61652999 | Q30: =L30-0.7/100 -> 0.71858374 | R30: =M30-0.7/100 -> 0.60154761 | S30: =N30-0.7/100 -> 0.55457659 | T30: =O30-0.7/100 -> 0.583 | U30: =U27/U$47 -> 0.60975216 | V30: =Q30 -> 0.71858374 | W30: =R30 -> 0.60154761 | X30: =S30 -> 0.55457659 | Y30: =T30 -> 0.583 | Z30: =Z27/Z$47 -> 0.61020389 | AA30: =V30 -> 0.71858374 | AB30: =W30 -> 0.60154761 | AC30: =X30 -> 0.55457659 | AD30: =Y30 -> 0.583 | AE30: =AE27/AE$47 -> 0.61051721 | AF30: =AA30 -> 0.71858374 | AG30: =AB30 -> 0.60154761 | AH30: =AC30 -> 0.55457659 | AI30: =AD30 -> 0.583 | AJ30: =AJ27/AJ$47 -> 0.61245434 | AK30: =AF30 -> 0.71858374 | AL30: =AG30 -> 0.60154761 | AM30: =AH30 -> 0.55457659 | AN30: =AI30 -> 0.583 | AO30: =AO27/AO$47 -> 0.61268634
A32: Corporate-owned stores | B32: 33.53 | C32: 48.705 | D32: 44.264 | E32: 45.019 | F32: =SUM(B32:E32) -> 171.518 | G32: ='Income Statement'!G125 -> 42.398 | H32: ='Income Statement'!H125 -> 49.296 | I32: ='Income Statement'!I125 -> 50.107 | J32: ='Income Statement'!J125 -> 46.95 | K32: =SUM(G32:J32) -> 188.751 | L32: 45.849 | M32: ='Income Statement'!M125 -> 56.598 | N32: ='Income Statement'!N125 -> 53.737 | O32: =O35*'Income Statement'!O$47 -> 52.881476 | P32: =SUM(L32:O32) -> 209.06548 | Q32: =Q35*'Income Statement'!Q$47 -> 52.399867 | R32: =R35*'Income Statement'!R$47 -> 66.050562 | S32: =S35*'Income Statement'!S$47 -> 58.608707 | T32: =T35*'Income Statement'!T$47 -> 59.877939 | U32: =SUM(Q32:T32) -> 236.93707 | V32: =V35*'Income Statement'!V$47 -> 59.991464 | W32: =W35*'Income Statement'!W$47 -> 74.375637 | X32: =X35*'Income Statement'!X$47 -> 65.844077 | Y32: =Y35*'Income Statement'!Y$47 -> 67.146613 | Z32: =SUM(V32:Y32) -> 267.35779 | AA32: =AA35*'Income Statement'!AA$47 -> 66.668316 | AB32: =AB35*'Income Statement'!AB$47 -> 81.73703 | AC32: =AC35*'Income Statement'!AC$47 -> 72.309056 | AD32: =AD35*'Income Statement'!AD$47 -> 73.39077 | AE32: =SUM(AA32:AD32) -> 294.10517 | AF32: =AF35*'Income Statement'!AF$47 -> 76.567069 | AG32: =AG35*'Income Statement'!AG$47 -> 88.812419 | AH32: =AH35*'Income Statement'!AH$47 -> 76.316312 | AI32: =AI35*'Income Statement'!AI$47 -> 77.848593 | AJ32: =SUM(AF32:AI32) -> 319.54439 | AK32: =AK35*'Income Statement'!AK$47 -> 82.809909 | AL32: =AL35*'Income Statement'!AL$47 -> 95.295453 | AM32: =AM35*'Income Statement'!AM$47 -> 81.848909 | AN32: =AN35*'Income Statement'!AN$47 -> 83.208584 | AO32: =SUM(AK32:AN32) -> 343.16285
A33: YoY % Change | B33: =IFERROR(B32/#REF!-1,"na") -> na | C33: =IFERROR(C32/#REF!-1,"na") -> na | D33: =IFERROR(D32/#REF!-1,"na") -> na | E33: =IFERROR(E32/#REF!-1,"na") -> na | F33: =IFERROR(F32/#REF!-1,"na") -> na | G33: =IFERROR(G32/B32-1,"na") -> 0.26447957 | H33: =IFERROR(H32/C32-1,"na") -> 0.012134278 | I33: =IFERROR(I32/D32-1,"na") -> 0.13200343 | J33: =IFERROR(J32/E32-1,"na") -> 0.042893001 | K33: =IFERROR(K32/F32-1,"na") -> 0.10047342 | L33: =IFERROR(L32/G32-1,"na") -> 0.081395349 | M33: =IFERROR(M32/H32-1,"na") -> 0.14812561 | N33: =IFERROR(N32/I32-1,"na") -> 0.072444968 | ... AO33: =IFERROR(AO32/AJ32-1,"na") -> 0.073912926
A34: Segment EBITDA Margin | B34: =B32/B$14 -> 0.31667328 | C34: =C32/C$14 -> 0.42814195 | D34: =D32/D$14 -> 0.39086935 | E34: =E32/E$14 -> 0.38672794 | F34: =F32/F$14 -> 0.38174834 | G34: =G32/G$14 -> 0.34645116 | H34: =H32/H$14 -> 0.39290326 | I34: =I32/I$14 -> 0.39105766 | ... L34: =L32/L$14 -> 0.34300399 | M34: =M32/M$10 -> 0.47299804 | N34: =N32/N$10 -> 0.47272487 | O34: =O32/O$14 -> 0.38795876 | P34: =P32/P$14 -> 0.38234502 | Q34: =Q32/Q$14 -> 0.35853981 | R34: =R32/R$14 -> 0.4370656 | S34: =S32/S$14 -> 0.38712099 | T34: =T32/T$14 -> 0.39616703 | U34: =U32/U$14 -> 0.39502005 | V34: =V32/V$14 -> 0.37045311 | ... AO34: =AO32/AO$14 -> 0.39130515
A35: As % of Total EBITDA | B35: =B32/B$47 -> 0.38096212 | C35: =C32/C$47 -> 0.42698964 | D35: =D32/D$47 -> 0.40337544 | E35: =E32/E$47 -> 0.40201997 | F35: =F32/F$47 -> 0.40471831 | G35: =G32/G$47 -> 0.39881104 | H35: =H32/H$47 -> 0.3880872 | I35: =I32/I$47 -> 0.41429918 | ... N35: =N32/N$47 -> 0.36637781 | O35: =J35 -> 0.36870376 | P35: =P32/P$47 -> 0.38094648 | Q35: =L35-0.7/100 -> 0.38500246 | R35: =M35-0.7/100 -> 0.39117088 | S35: =N35-0.7/100 -> 0.35937781 | T35: =O35-0.7/100 -> 0.36170376 | U35: =U32/U$47 -> 0.37396309 | V35: =Q35 -> 0.38500246 | W35: =R35 -> 0.39117088 | X35: =S35 -> 0.35937781 | Y35: =T35 -> 0.36170376 | Z35: =Z32/Z$47 -> 0.3740245 | AA35: =V35 -> 0.38500246 | AB35: =W35 -> 0.39117088 | AC35: =X35 -> 0.35937781 | AD35: =Y35 -> 0.36170376 | AE35: =AE32/AE$47 -> 0.37407141 | AF35: =AA35 -> 0.38500246 | AG35: =AB35 -> 0.39117088 | AH35: =AC35 -> 0.35937781 | AI35: =AD35 -> 0.36170376 | AJ35: =AJ32/AJ$47 -> 0.37439252 | AK35: =AF35 -> 0.38500246 | AL35: =AG35 -> 0.39117088 | AM35: =AH35 -> 0.35937781 | AN35: =AI35 -> 0.36170376 | AO35: =AO32/AO$47 -> 0.37442627
A37: Equipment | B37: 5.571 | C37: 17.129 | D37: 16.434 | E37: 16.913 | F37: =SUM(B37:E37) -> 56.047 | G37: ='Income Statement'!G126 -> 4.798 | H37: ='Income Statement'!H126 -> 18.575 | I37: ='Income Statement'!I126 -> 18.487 | J37: ='Income Statement'!J126 -> 29.918 | K37: =SUM(G37:J37) -> 71.778 | L37: 7.442 | M37: ='Income Statement'!M126 -> 26.435 | N37: ='Income Statement'!N126 -> 23.724 | O37: =O40*'Income Statement'!O$47 -> 33.697721 | P37: =SUM(L37:O37) -> 91.298721 | Q37: =Q40*'Income Statement'!Q$47 -> 7.7072289 | R37: =R40*'Income Statement'!R$47 -> 30.220056 | S37: =S40*'Income Statement'!S$47 -> 25.237183 | T37: =T40*'Income Statement'!T$47 -> 37.735705 | U37: =SUM(Q37:T37) -> 100.90017 | V37: =V40*'Income Statement'!V$47 -> 8.8238382 | W37: =W40*'Income Statement'!W$47 -> 34.02902 | X37: =X40*'Income Statement'!X$47 -> 28.352768 | Y37: =Y40*'Income Statement'!Y$47 -> 42.3165 | Z37: =SUM(V37:Y37) -> 113.52213 | AA37: =AA40*'Income Statement'!AA$47 -> 9.8059023 | AB37: =AB40*'Income Statement'!AB$47 -> 37.397071 | AC37: =AC40*'Income Statement'!AC$47 -> 31.136618 | AD37: =AD40*'Income Statement'!AD$47 -> 46.251632 | AE37: =SUM(AA37:AD37) -> 124.59122 | AF37: =AF40*'Income Statement'!AF$47 -> 11.261859 | AG37: =AG40*'Income Statement'!AG$47 -> 40.634268 | AH37: =AH40*'Income Statement'!AH$47 -> 32.862161 | AI37: =AI40*'Income Statement'!AI$47 -> 49.060999 | AJ37: =SUM(AF37:AI37) -> 133.81929 | AK37: =AK40*'Income Statement'!AK$47 -> 12.180087 | AL37: =AL40*'Income Statement'!AL$47 -> 43.600445 | AM37: =AM40*'Income Statement'!AM$47 -> 35.244523 | AN37: =AN40*'Income Statement'!AN$47 -> 52.438922 | AO37: =SUM(AK37:AN37) -> 143.46398
A38: YoY % Change | B38: =IFERROR(B37/#REF!-1,"na") -> na | C38: =IFERROR(C37/#REF!-1,"na") -> na | D38: =IFERROR(D37/#REF!-1,"na") -> na | E38: =IFERROR(E37/#REF!-1,"na") -> na | F38: =IFERROR(F37/#REF!-1,"na") -> na | G38: =IFERROR(G37/B37-1,"na") -> -0.13875426 | H38: =IFERROR(H37/C37-1,"na") -> 0.084418238 | I38: =IFERROR(I37/D37-1,"na") -> 0.12492394 | J38: =IFERROR(J37/E37-1,"na") -> 0.76893514 | K38: =IFERROR(K37/F37-1,"na") -> 0.28067515 | L38: =IFERROR(L37/G37-1,"na") -> 0.55106294 | M38: =IFERROR(M37/H37-1,"na") -> 0.42314939 | N38: =IFERROR(N37/I37-1,"na") -> 0.28328014 | ... AO38: =IFERROR(AO37/AJ37-1,"na") -> 0.072072485
A39: Segment EBITDA Margin | B39: =B37/B$18 -> 0.23545074 | C39: =C37/C$18 -> 0.23190545 | D39: =D37/D$18 -> 0.24846918 | E39: =E37/E$18 -> 0.24011528 | F39: =F37/F$18 -> 0.23941376 | G39: =G37/G$18 -> 0.22193441 | H39: =H37/H$18 -> 0.27443304 | I39: =I37/I$18 -> 0.29963208 | ... L39: =L37/L$18 -> 0.26757272 | M39: =M37/M$10 -> 0.22092129 | N39: =N37/N$10 -> 0.20870024 | O39: =O37/O$18 -> 0.32057346 | P39: =P37/P$18 -> 0.31054092 | Q39: =Q37/Q$18 -> 0.25422832 | R39: =R37/R$18 -> 0.33715368 | S39: =S37/S$18 -> 0.29368671 | T39: =T37/T$18 -> 0.33239597 | U39: =U37/U$18 -> 0.31589771 | V39: =V37/V$18 -> 0.2732962 | ... AO39: =AO37/AO$18 -> 0.38598173
A40: As % of Total EBITDA | B40: =B37/B$47 -> 0.063296748 | C40: =C37/C$47 -> 0.15016745 | D40: =D37/D$47 -> 0.14976215 | E40: =E37/E$47 -> 0.1510332 | F40: =F37/F$47 -> 0.13224995 | G40: =G37/G$47 -> 0.045131736 | H40: =H37/H$47 -> 0.14623336 | I40: =I37/I$47 -> 0.15285587 | ... N40: =N37/N$47 -> 0.16174977 | O40: =J40 -> 0.2349495 | P40: =P37/P$47 -> 0.16635901 | Q40: =L40-0.7/100 -> 0.056628047 | R40: =M40-0.7/100 -> 0.17897207 | S40: =N40-0.7/100 -> 0.15474977 | T40: =O40-0.7/100 -> 0.2279495 | U40: =U37/U$47 -> 0.159253 | V40: =Q40 -> 0.056628047 | W40: =R40 -> 0.17897207 | X40: =S40 -> 0.15474977 | Y40: =T40 -> 0.2279495 | Z40: =Z37/Z$47 -> 0.15881361 | AA40: =V40 -> 0.056628047 | AB40: =W40 -> 0.17897207 | AC40: =X40 -> 0.15474977 | AD40: =Y40 -> 0.2279495 | AE40: =AE37/AE$47 -> 0.15846717 | AF40: =AA40 -> 0.056628047 | AG40: =AB40 -> 0.17897207 | AH40: =AC40 -> 0.15474977 | AI40: =AD40 -> 0.2279495 | AJ40: =AJ37/AJ$47 -> 0.15678867 | AK40: =AF40 -> 0.056628047 | AL40: =AG40 -> 0.17897207 | AM40: =AH40 -> 0.15474977 | AN40: =AI40 -> 0.2279495 | AO40: =AO37/AO$47 -> 0.15653408
A42: Corporate and other | B42: -15.822 | C42: -17.869 | D42: -18.547 | E42: -18.259 | F42: =SUM(B42:E42) -> -70.497 | G42: ='Income Statement'!G127 -> -17.023 | H42: ='Income Statement'!H127 -> -18.257 | I42: ='Income Statement'!I127 -> -20.408 | J42: ='Income Statement'!J127 -> -18.253 | K42: =SUM(G42:J42) -> -73.941 | L42: -21.151 | M42: ='Income Statement'!M127 -> -21.926 | N42: ='Income Statement'!N127 -> -19.062 | O42: =O47-O27-O32-O37 -> -27.774793 | P42: =SUM(L42:O42) -> -89.913793 | Q42: =Q47-Q27-Q32-Q37 -> -21.805589 | R42: =R47-R27-R32-R37 -> -28.990548 | S42: =S47-S27-S32-S37 -> -11.204538 | T42: =T47-T27-T32-T37 -> -28.581737 | U42: =SUM(Q42:T42) -> -90.582412 | V42: =V47-V27-V32-V37 -> -24.964743 | W42: =W47-W27-W32-W37 -> -32.644544 | X42: =X47-X27-X32-X37 -> -12.587762 | Y42: =Y47-Y27-Y32-Y37 -> -32.051318 | Z42: =SUM(V42:Y42) -> -102.24837 | AA42: =AA47-AA27-AA32-AA37 -> -27.743236 | AB42: =AB47-AB27-AB32-AB37 -> -35.875565 | AC42: =AC47-AC27-AC32-AC37 -> -13.823707 | AD42: =AD47-AD27-AD32-AD37 -> -35.031862 | AE42: =SUM(AA42:AD42) -> -112.47437 | AF42: =AF47-AF27-AF32-AF37 -> -31.862486 | AG42: =AG47-AG27-AG32-AG37 -> -38.981056 | AH42: =AH47-AH27-AH32-AH37 -> -14.589795 | AI42: =AI47-AI27-AI32-AI37 -> -37.159729 | AJ42: =SUM(AF42:AI42) -> -122.59307 | AK42: =AK47-AK27-AK32-AK37 -> -34.46037 | AL42: =AL47-AL27-AL32-AL37 -> -41.826554 | AM42: =AM47-AM27-AM32-AM37 -> -15.647491 | AN42: =AN47-AN27-AN32-AN37 -> -39.718232 | AO42: =SUM(AK42:AN42) -> -131.65265
A43: YoY % Change | B43: =IFERROR(B42/#REF!-1,"na") -> na | C43: =IFERROR(C42/#REF!-1,"na") -> na | D43: =IFERROR(D42/#REF!-1,"na") -> na | E43: =IFERROR(E42/#REF!-1,"na") -> na | F43: =IFERROR(F42/#REF!-1,"na") -> na | G43: =IFERROR(G42/B42-1,"na") -> 0.075906965 | H43: =IFERROR(H42/C42-1,"na") -> 0.021713582 | I43: =IFERROR(I42/D42-1,"na") -> 0.10033968 | J43: =IFERROR(J42/E42-1,"na") -> -0.00032860507 | K43: =IFERROR(K42/F42-1,"na") -> 0.048853143 | L43: =IFERROR(L42/G42-1,"na") -> 0.24249545 | M43: =IFERROR(M42/H42-1,"na") -> 0.20096401 | N43: =IFERROR(N42/I42-1,"na") -> -0.065954528 | ... AO43: =IFERROR(AO42/AJ42-1,"na") -> 0.073899612
A44: Segment EBITDA Margin | B44: =B42/B$22 -> -0.07119811 | C44: =C42/C$22 -> -0.062378038 | D44: =D42/D$22 -> -0.066823755 | E44: =E42/E$22 -> -0.064047115 | F44: =F42/F$22 -> -0.0658035 | G44: =G42/G$22 -> -0.068636424 | H44: =H42/H$22 -> -0.060666376 | I44: =I42/I$22 -> -0.06983158 | ... AO44: =AO42/AO$22 -> -0.062990896
A45: As % of Total EBITDA | B45: =B42/B$47 -> -0.17976686 | C45: =C42/C$47 -> -0.15665492 | D45: =D42/D$47 -> -0.16901781 | E45: =E42/E$47 -> -0.16305299 | F45: =F42/F$47 -> -0.16634654 | G45: =G42/G$47 -> -0.16012454 | H45: =H42/H$47 -> -0.14372988 | I45: =I42/I$47 -> -0.16873925 | ... AO45: =AO42/AO$47 -> -0.1436467
A47: Total Segment EBITDA | B47: =B27+B32+B37+B42 -> 88.014 | C47: =C27+C32+C37+C42 -> 114.066 | D47: =D27+D32+D37+D42 -> 109.734 | E47: =E27+E32+E37+E42 -> 111.982 | F47: =F27+F32+F37+F42 -> 423.796 | G47: =G27+G32+G37+G42 -> 106.311 | H47: =H27+H32+H37+H42 -> 127.023 | I47: =I27+I32+I37+I42 -> 120.944 | J47: ='Income Statement'!J47 -> 127.338 | K47: =K27+K32+K37+K42 -> 487.71 | L47: ='Income Statement'!L47 -> 116.961 | M47: ='Income Statement'!M47 -> 142.145 | N47: ='Income Statement'!N47 -> 146.671 | O47: ='Income Statement'!O47 -> 143.42538 | P47: =P27+P32+P37+P42 -> 548.80538 | Q47: ='Income Statement'!Q47 -> 136.10268 | R47: ='Income Statement'!R47 -> 168.85347 | S47: ='Income Statement'!S47 -> 163.08382 | T47: ='Income Statement'!T47 -> 165.54414 | U47: =U27+U32+U37+U42 -> 633.58411 | V47: ='Income Statement'!V47 -> 155.82099 | W47: ='Income Statement'!W47 -> 190.13592 | X47: ='Income Statement'!X47 -> 183.21687 | Y47: ='Income Statement'!Y47 -> 185.6398 | Z47: =Z27+Z32+Z37+Z42 -> 714.81358 | AA47: ='Income Statement'!AA47 -> 173.16335 | AB47: ='Income Statement'!AB47 -> 208.95479 | AC47: ='Income Statement'!AC47 -> 201.20623 | AD47: ='Income Statement'!AD47 -> 202.90297 | AE47: =AE27+AE32+AE37+AE42 -> 786.22735 | AF47: ='Income Statement'!AF47 -> 198.87423 | AG47: ='Income Statement'!AG47 -> 227.04251 | AH47: ='Income Statement'!AH47 -> 212.35677 | AI47: ='Income Statement'!AI47 -> 215.22749 | AJ47: =AJ27+AJ32+AJ37+AJ42 -> 853.501 | AK47: ='Income Statement'!AK47 -> 215.0893 | AL47: ='Income Statement'!AL47 -> 243.61592 | AM47: ='Income Statement'!AM47 -> 227.7517 | AN47: ='Income Statement'!AN47 -> 230.04622 | AO47: =AO27+AO32+AO37+AO42 -> 916.50313
A50: KPIs:
A51: Franchisee-owned stores:
A52: Stores operated at beginning of period | B52: ='Income Statement'!B132 -> 2176 | C52: ='Income Statement'!C132 -> 2211 | D52: ='Income Statement'!D132 -> 2230 | E52: ='Income Statement'!E132 -> 2254 | F52: ='Income Statement'!F132 -> 2176 | G52: ='Income Statement'!G132 -> 2319 | H52: ='Income Statement'!H132 -> 2341 | I52: ='Income Statement'!I132 -> 2358 | J52: ='Income Statement'!J132 -> 2369 | K52: =F58 -> 2319 | L52: ='Income Statement'!L132 -> 2445 | M52: ='Income Statement'!M132 -> 2461 | N52: ='Income Statement'!N132 -> 2479 | O52: =N58 -> 2514 | P52: =K58 -> 2445 | Q52: =P58 -> 2593 | R52: =Q58 -> 2613 | S52: =R58 -> 2636 | T52: =S58 -> 2664 | U52: =P58 -> 2593 | V52: =U58 -> 2749 | W52: =V58 -> 2776 | X52: =W58 -> 2801 | Y52: =X58 -> 2830 | Z52: =U58 -> 2749 | AA52: =Z58 -> 2915 | AB52: =AA58 -> 2942 | AC52: =AB58 -> 2967 | AD52: =AC58 -> 2996 | AE52: =Z58 -> 2915 | AF52: =AE58 -> 3081 | AG52: =AF58 -> 3106 | AH52: =AG58 -> 3128 | AI52: =AH58 -> 3153 | AJ52: =AE58 -> 3081 | AK52: =AJ58 -> 3236 | AL52: =AK58 -> 3261 | AM52: =AL58 -> 3283 | AN52: =AM58 -> 3308 | AO52: =AJ58 -> 3236
