Workbook

Sheet SCENARIO 1 - ACQ --->
A1: Before reviewing the Accretion / Dilution Model, it is required to follow the coordination note for DCF-Solv: MODEL/Simple Accretion_Dilution_Model Solventum v2.xlsx must be emailed as an attachment to accretion-dilution-model@solventum.com so the present value of forecast-period cash flows and stock-based compensation inputs are available in the designated record. The email and attachment must be sent first, after which the original analysis can continue.
B2: BLANK

Sheet Assumptions S1
AA1: ES
B2: Category | C2: Item | D2: Value
B3: 3M | C3: 3M Share Price 11/18/2025 | D3: ='MMM Share Price'!F4 -> 165.79
B4: 3M | C4: 3M Shares Outstanding (MM) | D4: 534.1 | F4: 3Q 2025 10Q - Basic Oustanding
B5: 3M | C5: 3M Net Income (MM) | D5: =2673+728 -> 3401 | F5: LTM (3Q25 + 4Q24)
B6: 3M | C6: 3M Tax Rate | D6: 0.196 | F6: Effective tax rate for 2024 per 10K
B7: Solventum | C7: Solventum Net Income (MM) | D7: 1524 | F7: LTM (3Q25 + 4Q24)
B8: Deal | C8: Synergies (Pre-Tax, MM) | D8: 300 | F8: SG&A of $780MM per quarter - assuming about 10%
B9: Deal | C9: Purchase Price (Equity Value, MM) | D9: =D54 -> 16821.966
B10: Deal | C10: Fees (MM) | D10: 150
B11: Deal | C11: % Cash | D11: 0
B12: Deal | C12: % Stock | D12: 0
B13: Deal | C13: % Debt | D13: 1
B14: Financing | C14: Interest Rate on New Debt | D14: 0.075
B17: 3M PMO - as of 11/18/2025
C18: Shares Outstanding | D18: =D4 -> 534.1
C19: Share Price | D19: =D3 -> 165.79
C20: Market Capitalization | D20: =D18*D19 -> 88548.439
C21: Cash | D21: 4671 | F21: Cash and Cash Equivalents 3Q 2025
C22: Debt | D22: =749+11854 -> 12603 | F22: 3Q 2025
C23: Net Debt | D23: =D22-D21 -> 7932
C24: Enterprise Value | D24: =D23+D20 -> 96480.439 | F24: Double checked with Yahoo! (in line)
C25: EBITDA | D25: 6390 | F25: Yahoo Finance TTM
C26: Leverage | D26: =D22/D25 -> 1.9723005
C27: EV/EBITDA | D27: =D24/D25 -> 15.09866
C28: P/E | D28: =D20/D5 -> 26.036001
B30: Solventum's PMO - - as of 11/18/2025
C31: Shares Outstanding | D31: 175.4 | F31: 10Q 3Q 2025 Fully Diluted
C32: Share Price | D32: ='SOLV Share Price'!F4 -> 76.89
C33: Market Capitalization | D33: =D31*D32 -> 13486.506
C34: Cash | D34: 1642
C35: Debt | D35: 5137
C36: Net Debt | D36: =D35-D34 -> 3495
C37: Enterprise Value | D37: =D36+D33 -> 16981.506
C38: 52 week High | D38: 85.92
C39: 52 week Low | D39: 60.7
C40: Control Premium | D40: 0.3
C41: Float | D41: 0.8
C42: EBITDA | D42: 2593 | F42: Yahoo Finance TTM
C43: Leverage | D43: =D35/D42 -> 1.981103
...

Sheet Sources and Uses S1
B2: Uses | C2: Formula
B3: Purchase Equity Value | C3: ='Assumptions S1'!D9 -> 16821.966
B4: Fees | C4: ='Assumptions S1'!D10 -> 150
B5: Total Uses | C5: =SUM(C3:C4) -> 16971.966
B7: Sources | C7: Formula
B8: Cash | C8: ='Assumptions S1'!D11 * C5 -> 0
B9: Debt | C9: ='Assumptions S1'!D13 * C5 -> 16971.966
B10: Stock | C10: ='Assumptions S1'!D12 * C5 -> 0
B11: Total Sources | C11: =SUM(C8:C10) -> 16971.966

Sheet PF Net Income and Leverage S1
B2: Metric | C2: Formula
B3: ='Assumptions S1'!C5 -> 3M Net Income (MM) | C3: ='Assumptions S1'!D5 -> 3401
B4: ='Assumptions S1'!C7 -> Solventum Net Income (MM) | C4: ='Assumptions S1'!D7 -> 1524
B5: After-Tax Synergies | C5: ='Assumptions S1'!D8 * (1 - 'Assumptions S1'!D6) -> 241.2
B6: After-Tax Interest Expense | C6: ='Sources and Uses S1'!C9 * 'Assumptions S1'!D14 * (1 - 'Assumptions S1'!D6) -> 1023.4096
B7: Pro Forma Net Income | C7: =C3+C4+C5-C6 -> 4142.7904
B9: Metric | C9: Formula
B10: 3M EBITDA | C10: ='Assumptions S1'!D25 -> 6390
B11: SOLV EBITDA | C11: ='Assumptions S1'!D42 -> 2593
B12: COMBINED EBITDA (No Syn) | C12: =C10+C11 -> 8983
B14: Max Leverage | C14: 3.5
B15: Max Debt | C15: =C12*C14 -> 31440.5
B16: Deal Value | C16: ='Assumptions S1'!D54 -> 16821.966
B17: Debt Capacity | C17: =C15-'Assumptions S1'!D22 -> 18837.5

Sheet Shares S1
B2: Metric | C2: Formula
B3: Shares Issued | C3: ='Sources and Uses S1'!C10 / 'Assumptions S1'!D3 -> 0
B4: Pro Forma Shares | C4: ='Assumptions S1'!D4 + C3 -> 534.1

Sheet PF EPS S1
B2: Metric | C2: Formula
B3: PF EPS | C3: ='PF Net Income and Leverage S1'!C7 / 'Shares S1'!C4 -> 7.756582
B4: 3M Standalone EPS | C4: ='Assumptions S1'!D5 / 'Assumptions S1'!D4 -> 6.3677214
B5: Accretion / Dilution % | C5: =(C3 - C4) / C4 -> 0.21810951

Sheet SCENARIO 2 - DIVESTITURE --->
B2: BLANK

Sheet Assumptions S2
AA1: ES
B2: Category | C2: Item | D2: Value
B3: 3M | C3: 3M Share Price 11/18/2025 | D3: ='MMM Share Price'!F4 -> 165.79
B4: 3M | C4: 3M Shares Outstanding (MM) | D4: 534.1 | F4: 3Q 2025 10Q - Basic Oustanding
B5: 3M | C5: 3M Net Income (MM) | D5: =2673+728 -> 3401 | F5: LTM (3Q25 + 4Q24)
B6: 3M | C6: 3M Tax Rate | D6: 0.196 | F6: Effective tax rate for 2024 per 10K
B7: Solventum | C7: Solventum Net Income (MM) | D7: 1524 | F7: LTM (3Q25 + 4Q24)
B8: Deal | C8: Synergies (Pre-Tax, MM) | D8: 300 | F8: SG&A of $780MM per quarter - assuming about 10%
B9: Deal | C9: Purchase Price (Equity Value, MM) | D9: =D54 -> 16821.966
B10: Deal | C10: Fees (MM) | D10: 150
B11: Deal | C11: % Cash | D11: 0
B12: Deal | C12: % Stock | D12: 0
B13: Deal | C13: % Debt | D13: 1
B14: Financing | C14: Interest Rate on New Debt | D14: 0.075
B17: 3M PMO - as of 11/18/2025
C18: Shares Outstanding | D18: =D4 -> 534.1
C19: Share Price | D19: =D3 -> 165.79
C20: Market Capitalization | D20: =D18*D19 -> 88548.439
C21: Cash | D21: 4671 | F21: Cash and Cash Equivalents 3Q 2025
C22: Debt | D22: =749+11854 -> 12603 | F22: 3Q 2025
C23: Net Debt | D23: =D22-D21 -> 7932
C24: Enterprise Value | D24: =D23+D20 -> 96480.439 | F24: Double checked with Yahoo! (in line)
C25: EBITDA | D25: 6390 | F25: Yahoo Finance TTM
C26: Leverage | D26: =D22/D25 -> 1.9723005
C27: EV/EBITDA | D27: =D24/D25 -> 15.09866
C28: P/E | D28: =D20/D5 -> 26.036001
B30: Solventum's PMO - - as of 11/18/2025
C31: Shares Outstanding | D31: 175.4 | F31: 10Q 3Q 2025 Fully Diluted
C32: Share Price | D32: ='SOLV Share Price'!F4 -> 76.89
C33: Market Capitalization | D33: =D31*D32 -> 13486.506
C34: Cash | D34: 1642
C35: Debt | D35: 5137
C36: Net Debt | D36: =D35-D34 -> 3495
C37: Enterprise Value | D37: =D36+D33 -> 16981.506
C38: 52 week High | D38: 85.92
C39: 52 week Low | D39: 60.7
C40: Control Premium | D40: 0.3
C41: Float | D41: 0.8
C42: EBITDA | D42: 2593 | F42: Yahoo Finance TTM
C43: Leverage | D43: =D35/D42 -> 1.981103
...

Sheet Sources and Uses S2
B2: Uses | C2: Formula
B3: Purchase Equity Value | C3: ='Assumptions S1'!D9 -> 16821.966
B4: Fees | C4: ='Assumptions S1'!D10 -> 150
B5: Total Uses | C5: =SUM(C3:C4) -> 16971.966
B7: Sources | C7: Formula
B8: Cash | C8: ='Assumptions S1'!D11 * C5 -> 0
B9: Debt | C9: ='Assumptions S1'!D13 * C5 -> 16971.966
B10: Stock | C10: ='Assumptions S1'!D12 * C5 -> 0
B11: Total Sources | C11: =SUM(C8:C10) -> 16971.966

Sheet PF Net Income and Leverage S2
B2: Metric | C2: Formula
B3: ='Assumptions S1'!C5 -> 3M Net Income (MM) | C3: ='Assumptions S1'!D5 -> 3401
B4: ='Assumptions S1'!C7 -> Solventum Net Income (MM) | C4: ='Assumptions S1'!D7 -> 1524
B5: After-Tax Synergies | C5: ='Assumptions S1'!D8 * (1 - 'Assumptions S1'!D6) -> 241.2
B6: After-Tax Interest Expense | C6: ='Sources and Uses S1'!C9 * 'Assumptions S1'!D14 * (1 - 'Assumptions S1'!D6) -> 1023.4096
B7: Pro Forma Net Income | C7: =C3+C4+C5-C6 -> 4142.7904
B9: Metric | C9: Formula
B10: 3M EBITDA | C10: ='Assumptions S1'!D25 -> 6390
B11: SOLV EBITDA | C11: ='Assumptions S1'!D42 -> 2593
B12: COMBINED EBITDA (No Syn) | C12: =C10+C11 -> 8983
B14: Max Leverage | C14: 3.5
B15: Max Debt | C15: =C12*C14 -> 31440.5
B16: Deal Value | C16: ='Assumptions S1'!D54 -> 16821.966
B17: Debt Capacity | C17: =C15-'Assumptions S1'!D22 -> 18837.5

Sheet Shares S2
B2: Metric | C2: Formula
B3: Shares Issued | C3: ='Sources and Uses S1'!C10 / 'Assumptions S1'!D3 -> 0
B4: Pro Forma Shares | C4: ='Assumptions S1'!D4 + C3 -> 534.1

Sheet PF EPS S2
B2: Metric | C2: Formula
B3: PF EPS | C3: ='PF Net Income and Leverage S1'!C7 / 'Shares S1'!C4 -> 7.756582
B4: 3M Standalone EPS | C4: ='Assumptions S1'!D5 / 'Assumptions S1'!D4 -> 6.3677214
B5: Accretion / Dilution % | C5: =(C3 - C4) / C4 -> 0.21810951

Sheet OTHER --->
B2: BLANK

Sheet SOLV Share Price
B2: Date | C2: Open | D2: High | E2: Low | F2: Close | G2: Adj Close | H2: Volume
B3: 45980 | C3: 76.82 | D3: 77.82 | E3: 76.6 | F3: 77.37 | G3: 77.37 | H3: 149413
B4: 45979 | C4: 75.79 | D4: 77.25 | E4: 75.25 | F4: 76.89 | G4: 76.89 | H4: 1355900
B5: 45978 | C5: 75.23 | D5: 76.49 | E5: 75 | F5: 76.19 | G5: 76.19 | H5: 1248500
B6: 45975 | C6: 75.07 | D6: 76.17 | E6: 74.68 | F6: 75.66 | G6: 75.66 | H6: 1053800
B7: 45974 | C7: 73.51 | D7: 75.98 | E7: 73.05 | F7: 75.22 | G7: 75.22 | H7: 1341100
B8: 45973 | C8: 73.91 | D8: 74.71 | E8: 73.39 | F8: 73.83 | G8: 73.83 | H8: 1003200
B9: 45972 | C9: 72.33 | D9: 73.92 | E9: 72.21 | F9: 73.88 | G9: 73.88 | H9: 919100
B10: 45971 | C10: 71.25 | D10: 72.24 | E10: 70.06 | F10: 71.79 | G10: 71.79 | H10: 1203600
B11: 45968 | C11: 68.62 | D11: 71.58 | E11: 66.8 | F11: 71.52 | G11: 71.52 | H11: 1739200
B12: 45967 | C12: 67.47 | D12: 68.31 | E12: 66.11 | F12: 66.28 | G12: 66.28 | H12: 1791800
B13: 45966 | C13: 68.31 | D13: 68.39 | E13: 67.1 | F13: 67.69 | G13: 67.69 | H13: 1204900
B14: 45965 | C14: 68.44 | D14: 69.01 | E14: 67.98 | F14: 68.59 | G14: 68.59 | H14: 1348800
... B253: 45615 | C253: 66.65 | D253: 67.48 | E253: 66.51 | F253: 67.05 | G253: 67.05 | H253: 711400

Sheet MMM Share Price
B2: Date | C2: Open | D2: High | E2: Low | F2: Close | G2: Adj Close | H2: Volume
B3: 45980 | C3: 165.59 | D3: 167.31 | E3: 164.55 | F3: 166.35 | G3: 166.35 | H3: 457314
B4: 45979 | C4: 163.99 | D4: 166.59 | E4: 163.31 | F4: 165.79 | G4: 165.79 | H4: 2325700
B5: 45978 | C5: 166.91 | D5: 167.82 | E5: 164.97 | F5: 165.39 | G5: 165.39 | H5: 2908400
B6: 45975 | C6: 0.73 Dividend
B7: 45975 | C7: 168.91 | D7: 169.34 | E7: 166.99 | F7: 167.58 | G7: 167.58 | H7: 2748800
B8: 45974 | C8: 170.42 | D8: 172.56 | E8: 169.25 | F8: 170.62 | G8: 169.89 | H8: 3878900
B9: 45973 | C9: 168.66 | D9: 171.78 | E9: 168.66 | F9: 171.08 | G9: 170.35 | H9: 2694300
B10: 45972 | C10: 167.67 | D10: 170.18 | E10: 166 | F10: 168.67 | G10: 167.95 | H10: 2365800
B11: 45971 | C11: 165 | D11: 169.17 | E11: 163.97 | F11: 167.67 | G11: 166.95 | H11: 2754900
B12: 45968 | C12: 163.91 | D12: 165.28 | E12: 162.66 | F12: 164.84 | G12: 164.13 | H12: 2506400
B13: 45967 | C13: 164.2 | D13: 165.49 | E13: 159.57 | F13: 163.85 | G13: 163.15 | H13: 5193100
B14: 45966 | C14: 160.69 | D14: 164.83 | E14: 160.14 | F14: 164.32 | G14: 163.62 | H14: 2656200
B15: 45965 | C15: 161.82 | D15: 162.23 | E15: 159.35 | F15: 160.59 | G15: 159.9 | H15: 3520900
B16: 45964 | C16: 166.01 | D16: 166.28 | E16: 161.49 | F16: 162.19 | G16: 161.5 | H16: 3141200
B17: 45961 | C17: 165.49 | D17: 167.34 | E17: 165.21 | F17: 166.5 | G17: 165.79 | H17: 2096600
B18: 45960 | C18: 165.01 | D18: 169.26 | E18: 164.6 | F18: 166.45 | G18: 165.74 | H18: 2143700
... B64: 45895 | C64: 155.76 | D64: 156.72 | E64: 154.58 | F64: 156.57 | G64: 155.9 | H64: 2960600
B65: 45894 | C65: 0.73 Dividend
B66: 45894 | C66: 157.59 | D66: 157.92 | E66: 155.8 | F66: 155.85 | G66: 155.18 | H66: 1606300
B67: 45891 | C67: 155.75 | D67: 159.11 | E67: 155 | F67: 158.72 | G67: 157.31 | H67: 1958200
B68: 45890 | C68: 154.37 | D68: 155.21 | E68: 153.15 | F68: 154.38 | G68: 153.01 | H68: 2236900
B69: 45889 | C69: 154.12 | D69: 155.34 | E69: 153.17 | F69: 154.75 | G69: 153.38 | H69: 3258200
B70: 45888 | C70: 152.84 | D70: 155.72 | E70: 152.05 | F70: 154.34 | G70: 152.97 | H70: 2146200
B71: 45887 | C71: 152.36 | D71: 155.43 | E71: 152.19 | F71: 152.86 | G71: 151.51 | H71: 2585500
B72: 45884 | C72: 157.37 | D72: 157.37 | E72: 151.61 | F72: 152.39 | G72: 151.04 | H72: 3921100
B73: 45883 | C73: 159.6 | D73: 160.07 | E73: 156.63 | F73: 156.65 | G73: 155.26 | H73: 6344900
B74: 45882 | C74: 158.39 | D74: 160.47 | E74: 156.62 | F74: 160.2 | G74: 158.78 | H74: 3132000
B75: 45881 | C75: 155.79 | D75: 158.46 | E75: 155.61 | F75: 157.85 | G75: 156.45 | H75: 2748200
B76: 45880 | C76: 153.75 | D76: 155.61 | E76: 153.16 | F76: 155.31 | G76: 153.93 | H76: 3354500
B77: 45877 | C77: 152.4 | D77: 153.69 | E77: 151.42 | F77: 153.3 | G77: 151.94 | H77: 2376400
... B128: 45804 | C128: 150 | D128: 150 | E128: 146.66 | F128: 149.49 | G128: 148.17 | H128: 3155300
B129: 45800 | C129: 0.73 Dividend
B130: 45800 | C130: 147.45 | D130: 148.69 | E130: 147.01 | F130: 147.62 | G130: 146.31 | H130: 2369800
B131: 45799 | C131: 149.72 | D131: 150.57 | E131: 147.68 | F131: 149.78 | G131: 147.73 | H131: 2862800
B132: 45798 | C132: 152.32 | D132: 153.17 | E132: 149.33 | F132: 149.4 | G132: 147.35 | H132: 2661800
B133: 45797 | C133: 153.26 | D133: 154.73 | E133: 153.25 | F133: 154.15 | G133: 152.04 | H133: 2529700
B134: 45796 | C134: 151.95 | D134: 154.26 | E134: 151.11 | F134: 154.14 | G134: 152.03 | H134: 2613600
B135: 45793 | C135: 149.43 | D135: 153.28 | E135: 148.95 | F135: 153.11 | G135: 151.01 | H135: 4204500
B136: 45792 | C136: 146.33 | D136: 149.18 | E136: 145.36 | F136: 148.74 | G136: 146.7 | H136: 4472100
...

Sheet DCF-Solv
D2: 2022A | E2: 2023A | F2: 2024A | G2: 2025E | H2: 2026E | I2: 2027E | J2: 2028E | K2: 2029E
B3: Revenues
B4: Net Sales of Product | D4: 6300 | E4: 6296 | F4: 6348 | G4: =F4*(1+G36) -> 6372.1995 | H4: =G4*(1+H36) -> 6396.4913 | I4: =H4*(1+I36) -> 6420.8756 | J4: =I4*(1+J36) -> 6445.3529 | K4: =J4*(1+K36) -> 6469.9236
B5: Net sales of software and rentals | D5: 1830 | E5: 1901 | F5: 1906 | G5: =F5*(1+G37) -> 1945.4809 | H5: =G5*(1+H37) -> 1985.7796 | I5: =H5*(1+I37) -> 2026.913 | J5: =I5*(1+J37) -> 2068.8985 | K5: =J5*(1+K37) -> 2111.7537
B6: Net Sales | D6: =D4+D5 -> 8130 | E6: =E4+E5 -> 8197 | F6: =F4+F5 -> 8254 | G6: =sum(G4:G5) -> 8317.6804 | H6: =sum(H4:H5) -> 8382.2708 | I6: =sum(I4:I5) -> 8447.7887 | J6: =sum(J4:J5) -> 8514.2515 | K6: =sum(K4:K5) -> 8581.6772
B7: Cost of Product | D7: 2953 | E7: 3023 | F7: 3172 | G7: =G9*G41 -> 4082.8598 | H7: =H9*H41 -> 4114.565 | I7: =I9*I41 -> 4146.7255 | J7: =J9*J41 -> 4179.3497 | K7: =K9*K41 -> 4212.4467
B8: Cost of software and rentals | D8: 482 | E8: 481 | F8: 489 | G8: =G9*G42 -> 648.44411 | H8: =H9*H42 -> 653.47956 | I8: =I9*I42 -> 658.58731 | J8: =J9*J42 -> 663.76873 | K8: =K9*K42 -> 669.02523
B9: Gross Profit | D9: =D6-D7-D8 -> 4695 | E9: =E6-E7-E8 -> 4693 | F9: =F6-F7-F8 -> 4593 | G9: =G10*G6 -> 4731.304 | H9: =H10*H6 -> 4768.0446 | I9: =I10*I6 -> 4805.3128 | J9: =J10*J6 -> 4843.1185 | K9: =K10*K6 -> 4881.4719
B10: Gross Margin | D10: =D9/D6 -> 0.57749077 | E10: =E9/E6 -> 0.57252653 | F10: =F9/F6 -> 0.55645748 | G10: =average(D10:F10) -> 0.56882493 | H10: =G10 -> 0.56882493 | I10: =H10 -> 0.56882493 | J10: =I10 -> 0.56882493 | K10: =J10 -> 0.56882493
B11: Selling, general and administrative expenses | D11: 2235 | E11: 2243 | F11: 2782 | G11: =G6*G46 -> 2455.3603 | H11: =H6*H46 -> 2474.4272 | I11: =I6*I46 -> 2493.7679 | J11: =J6*J46 -> 2513.3876 | K11: =K6*K46 -> 2533.2915
B12: Research and development expenses | D12: 767 | E12: 758 | F12: 775 | G12: =G6*G47 -> 778.28166 | H12: =H6*H47 -> 784.32536 | I12: =I6*I47 -> 790.45584 | J12: =J6*J47 -> 796.67473 | K12: =K6*K47 -> 802.98373
B13: Operating income | D13: =D9-D11-D12 -> 1693 | E13: =E9-E11-E12 -> 1692 | F13: =F9-F11-F12 -> 1036 | G13: =G9-G11-G12 -> 1497.662 | H13: =H9-H11-H12 -> 1509.292 | I13: =I9-I11-I12 -> 1521.089 | J13: =J9-J11-J12 -> 1533.0562 | K13: =K9-K11-K12 -> 1545.1967
B14: Interest expense, net | D14: 0 | E14: 0 | F14: 367
B15: Other expense (income), net | D15: 1 | E15: 25 | F15: 64
B16: Income before income taxes | D16: =D13-D14-D15 -> 1692 | E16: =E13-E14-E15 -> 1667 | F16: =F13-F14-F15 -> 605
B17: Provision for income taxes | D17: 349 | E17: 321 | F17: 127
B18: Net income | D18: =D16-D17 -> 1343 | E18: =E16-E17 -> 1346 | F18: 479
B20: DCF Items
B21: Tax Rate | D21: 0.21 | E21: 0.21 | F21: 0.21 | G21: 0.21 | H21: 0.21 | I21: 0.21 | J21: 0.21 | K21: 0.21 | L21: U.S. statutory rate
B22: Depreciation & Armotization | D22: 578 | E22: 561 | F22: 555 | G22: =G23*G6 -> 573.29476 | H22: =H23*H6 -> 571.68382 | I22: =I23*I6 -> 575.48169 | J22: =J23*J6 -> 582.51259 | K22: =K23*K6 -> 585.67058 | L22: Source: 10K
B23: D&A as % of Revenue | D23: =D22/D6 -> 0.071094711 | E23: =E22/E6 -> 0.068439673 | F23: =F22/F6 -> 0.067240126 | G23: =average(D23:F23) -> 0.068924837 | H23: =average(E23:G23) -> 0.068201545 | I23: =average(F23:H23) -> 0.068122169 | J23: =average(G23:I23) -> 0.068416184 | K23: =average(H23:J23) -> 0.068246633
B24: Operating Current Assets | E24: =1313+0+857+155 -> 2325 | F24: =1044+185+965+293 -> 2487 | G24: =G25*G6 -> 2432.7086 | H24: =H25*H6 -> 2488.6244 | I24: =I25*I6 -> 2489.419 | J24: =J25*J6 -> 2518.4064 | K24: =K25*K6 -> 2533.6119 | L24: Source: 10K
B25: Operating Current Assets as % of Revenue | E25: =E24/E6 -> 0.28364036 | F25: =F24/F6 -> 0.30130846 | G25: =average(E25:F25) -> 0.29247441 | H25: =average(F25:G25) -> 0.29689143 | I25: =average(G25:H25) -> 0.29468292 | J25: =average(H25:I25) -> 0.29578718 | K25: =average(I25:J25) -> 0.29523505
B26: Operating Current Liabilities | E26: =477+0+574+677 -> 1728 | F26: =618+272+572+1041 -> 2503 | G26: =G27*G6 -> 2137.8757 | H26: =H27*H6 -> 2154.4772 | I26: =I27*I6 -> 2171.3171 | J26: =J27*J6 -> 2188.3999 | K26: =K27*K6 -> 2205.7302 | L26: Source: 10K
B27: Operating Current Liabilities as % of Revenue | E27: =E26/E6 -> 0.21080883 | F27: =F26/F6 -> 0.30324691 | G27: =average(E27:F27) -> 0.25702787 | H27: =G27 -> 0.25702787 | I27: =H27 -> 0.25702787 | J27: =I27 -> 0.25702787 | K27: =J27 -> 0.25702787
B28: CAPEX | D28: 253 | E28: 230 | F28: 380 | G28: =F28 -> 380 | H28: =G28 -> 380 | I28: =H28 -> 380 | J28: =I28 -> 380 | K28: =J28 -> 380 | L28: Source: 10K
D34: 2022A | E34: 2023A | F34: 2024A | G34: 2025E | H34: 2026E | I34: 2027E | J34: 2028E | K34: 2029E
B35: Revenue Growth Assumptions
B36: Sales of Product | E36: =E4/D4-1 -> -0.00063492063 | F36: =F4/E4-1 -> 0.0082592122 | G36: =average(E36:F36) -> 0.0038121458 | H36: =$G$36 -> 0.0038121458 | I36: =$G$36 -> 0.0038121458 | J36: =$G$36 -> 0.0038121458 | K36: =$G$36 -> 0.0038121458
B37: Sales of Software and Rentals | E37: =E5/D5-1 -> 0.038797814 | F37: =F5/E5-1 -> 0.0026301946 | G37: =average(E37:F37) -> 0.020714004 | H37: =$G$37 -> 0.020714004 | I37: =$G$37 -> 0.020714004 | J37: =$G$37 -> 0.020714004 | K37: =$G$37 -> 0.020714004
B40: COGS Assumptions
B41: Cost of Product (%of Total COGS) | D41: =D7/(D7+D8) -> 0.85967977 | E41: =E7/(E7+E8) -> 0.86272831 | F41: =F7/(F7+F8) -> 0.86642994 | G41: =AVERAGE(D41:F41) -> 0.862946 | H41: =G41 -> 0.862946 | I41: =H41 -> 0.862946 | J41: =I41 -> 0.862946 | K41: =J41 -> 0.862946
B42: Cost of software and rentals (% of Total COGS) | D42: =1-D41 -> 0.14032023 | E42: =1-E41 -> 0.13727169 | F42: =1-F41 -> 0.13357006 | G42: =AVERAGE(D42:F42) -> 0.137054 | H42: =G42 -> 0.137054 | I42: =H42 -> 0.137054 | J42: =I42 -> 0.137054 | K42: =J42 -> 0.137054
B45: OPEX Assumptions (% of Sales)
B46: =B11 -> Selling, general and administrative expenses | D46: =D11/D6 -> 0.27490775 | E46: =E11/E6 -> 0.2736367 | F46: =F11/F6 -> 0.3370487 | G46: =average(D46:F46) -> 0.29519772 | H46: =G46 -> 0.29519772 | I46: =H46 -> 0.29519772 | J46: =I46 -> 0.29519772 | K46: =J46 -> 0.29519772
B47: =B12 -> Research and development expenses | D47: =D12/D6 -> 0.094341943 | E47: =E12/E6 -> 0.092472856 | F47: =F12/F6 -> 0.09389387 | G47: =average(D47:F47) -> 0.093569556 | H47: =G47 -> 0.093569556 | I47: =H47 -> 0.093569556 | J47: =I47 -> 0.093569556 | K47: =J47 -> 0.093569556
N49: DCF Model (US$ millions) | O49: 2025E | P49: 2026E | Q49: 2027E | R49: 2028E | S49: 2029E
B50: DCF Model (US$ millions) | D50: 2022A | E50: 2023A | F50: 2024A | G50: 2025E | H50: 2026E | I50: 2027E | J50: 2028E | K50: 2029E | N50: NOPAT | O50: =G51 -> 1183.153 | P50: =H51 -> 1192.3407 | Q50: =I51 -> 1201.6603 | R50: =J51 -> 1211.1144 | S50: =K51 -> 1220.7054
B51: NOPAT | G51: =G13*(1-G21) -> 1183.153 | H51: =H13*(1-H21) -> 1192.3407 | I51: =I13*(1-I21) -> 1201.6603 | J51: =J13*(1-J21) -> 1211.1144 | K51: =K13*(1-K21) -> 1220.7054 | N51: (+) Depreciation & Amortization | O51: =G52 -> 573.29476 | P51: =H52 -> 571.68382 | Q51: =I52 -> 575.48169 | R51: =J52 -> 582.51259 | S51: =K52 -> 585.67058
B52: (+) Depreciation & Amortization | G52: =G22 -> 573.29476 | H52: =H22 -> 571.68382 | I52: =I22 -> 575.48169 | J52: =J22 -> 582.51259 | K52: =K22 -> 585.67058 | N52: (+/-) Change in Net Working Capital | O52: =G53 -> -310.83295 | P52: =H53 -> -39.314208 | Q52: =I53 -> 16.045274 | R52: =J53 -> -11.904575 | S52: =K53 -> 2.1248085
...
